Workbook

Sheet 종합

Sheet 기본-타자
A1: RK | B1: Player | C1: Pos | D1: Team | E1: Year | F1: WAR | G1: wRC+ | H1: off | I1: def | J1: G | K1: PA | L1: AB | M1: R | N1: H | O1: 2B | P1: 3B | Q1: HR | R1: RBI | S1: SB | T1: CS | U1: BB | V1: HBP | W1: IB | X1: SO | Y1: GDP | Z1: SF | AA1: BA | AB1: OBP | AC1: SLG | AD1: OPS | AE1: wOBA | AF1: PosAdj | AG1: pos | AH1: PF | AI1: whiff% | AJ1: chase% | AK1: WPA | AL1: RE24 | AM1: REW | AN1: RC27 | AO1: OAA | AP1: PA | AQ1: 국적
A2: 1 | B2: 오스틴 | C2: ='연도별 상수'!AE$3 -> 1B | D2: LG | E2: ='연도별 상수'!$A$46 -> 2026 | F2: =ROUND(((H2)+(I2)+(AG2*K2/600)+(20*K2/600))/'연도별 상수'!$U$46,2) -> 4.49 | G2: =ROUND(100*(((((AE2-'리그 타자'!$B$46)/'연도별 상수'!$T$46)+'연도별 상수'!$W$46))+('연도별 상수'!$W$46*(1-AH2)))/'연도별 상수'!$W$46,1) -> 189.2 | H2: =ROUND((((AE2-'리그 타자'!$B$46)/'연도별 상수'!$T$46)*K2/AH2)+(S2*'연도별 상수'!$AB$46-T2*'연도별 상수'!$AC$46)-((S2+T2)*('연도별 상수'!$AD$46*0.2-(1-'연도별 상수'!$AD$46)*0.4))+0.05*(S2+O2+P2),1) -> 43.9 | I2: =ROUND((0.75*AO2)+(AF2*(J2/144)),1) -> -3 | J2: 85 | K2: 378 | L2: 327 | M2: 69 | N2: 111 | O2: 18 | P2: 3 | Q2: 27 | R2: 83 | S2: 2 | T2: 1 | U2: 42 | V2: 6 | W2: 4 | X2: 58 | Y2: 6 | Z2: 3 | AA2: =ROUND(N2/L2,3) -> 0.339 | AB2: =ROUND((N2+U2+V2)/(L2+U2+V2+Z2),3) -> 0.421 | AC2: =ROUND(((N2-O2-P2-Q2)+2*O2+3*P2+4*Q2)/L2,3) -> 0.661 | AD2: =ROUND(AB2+AC2,3) -> 1.082 | AE2: =ROUND((('연도별 상수'!$N$46*(U2-W2))+('연도별 상수'!$O$46*V2)+('연도별 상수'!$P$46*(N2-O2-P2-Q2))+('연도별 상수'!$Q$46*O2)+('연도별 상수'!$R$46*P2)+('연도별 상수'!$S$46*Q2))/(L2+U2+V2-W2+Z2),3) -> 0.469 | AF2: ='연도별 상수'!AG$3 -> -10.22 | AG2: ='연도별 상수'!AH$3 -> -8 | AH2: ='연도별 상수'!$B$46 -> 0.871842 | AI2: 0 | AJ2: 0 | AK2: 0 | AL2: 0 | AM2: 0 | AN2: 0 | AO2: 4 | AP2: =K2 -> 378 | AQ2: 1
A3: 2 | B3: 김주원 | C3: ='연도별 상수'!AE$6 -> SS | D3: NC | E3: ='연도별 상수'!$A$46 -> 2026 | F3: =ROUND(((H3)+(I3)+(AG3*K3/600)+(20*K3/600))/'연도별 상수'!$U$46,2) -> 3.77 | G3: =ROUND(100*(((((AE3-'리그 타자'!$B$46)/'연도별 상수'!$T$46)+'연도별 상수'!$W$46))+('연도별 상수'!$W$46*(1-AH3)))/'연도별 상수'!$W$46,1) -> 129.7 | H3: =ROUND((((AE3-'리그 타자'!$B$46)/'연도별 상수'!$T$46)*K3/AH3)+(S3*'연도별 상수'!$AB$46-T3*'연도별 상수'!$AC$46)-((S3+T3)*('연도별 상수'!$AD$46*0.2-(1-'연도별 상수'!$AD$46)*0.4))+0.05*(S3+O3+P3),1) -> 16 | I3: =ROUND((0.75*AO3)+(AF3*(J3/144)),1) -> 8.3 | J3: 81 | K3: 366 | L3: 320 | M3: 55 | N3: 98 | O3: 15 | P3: 0 | Q3: 13 | R3: 40 | S3: 20 | T3: 4 | U3: 29 | V3: 13 | W3: 2 | X3: 49 | Y3: 1 | Z3: 3 | AA3: =ROUND(N3/L3,3) -> 0.306 | AB3: =ROUND((N3+U3+V3)/(L3+U3+V3+Z3),3) -> 0.384 | AC3: =ROUND(((N3-O3-P3-Q3)+2*O3+3*P3+4*Q3)/L3,3) -> 0.475 | AD3: =ROUND(AB3+AC3,3) -> 0.859 | AE3: =ROUND((('연도별 상수'!$N$46*(U3-W3))+('연도별 상수'!$O$46*V3)+('연도별 상수'!$P$46*(N3-O3-P3-Q3))+('연도별 상수'!$Q$46*O3)+('연도별 상수'!$R$46*P3)+('연도별 상수'!$S$46*Q3))/(L3+U3+V3-W3+Z3),3) -> 0.389 | AF3: ='연도별 상수'!AG$6 -> 2.77 | AG3: ='연도별 상수'!AH$6 -> 7 | AH3: ='연도별 상수'!$J$46 -> 0.968492 | AI3: 0 | AJ3: 0 | AK3: 0 | AL3: 0 | AM3: 0 | AN3: 0 | AO3: 9 | AP3: =K3 -> 366 | AQ3: 0
A4: 3 | B4: 김도영 | C4: ='연도별 상수'!AE$5 -> 3B | D4: KIA | E4: ='연도별 상수'!$A$46 -> 2026 | F4: =ROUND(((H4)+(I4)+(AG4*K4/600)+(20*K4/600))/'연도별 상수'!$U$46,2) -> 3.77 | G4: =ROUND(100*(((((AE4-'리그 타자'!$B$46)/'연도별 상수'!$T$46)+'연도별 상수'!$W$46))+('연도별 상수'!$W$46*(1-AH4)))/'연도별 상수'!$W$46,1) -> 163.9 | H4: =ROUND((((AE4-'리그 타자'!$B$46)/'연도별 상수'!$T$46)*K4/AH4)+(S4*'연도별 상수'!$AB$46-T4*'연도별 상수'!$AC$46)-((S4+T4)*('연도별 상수'!$AD$46*0.2-(1-'연도별 상수'!$AD$46)*0.4))+0.05*(S4+O4+P4),1) -> 31.1 | I4: =ROUND((0.75*AO4)+(AF4*(J4/144)),1) -> -2.1 | J4: 86 | K4: 371 | L4: 315 | M4: 69 | N4: 94 | O4: 17 | P4: 1 | Q4: 27 | R4: 74 | S4: 5 | T4: 0 | U4: 47 | V4: 5 | W4: 7 | X4: 61 | Y4: 7 | Z4: 4 | AA4: =ROUND(N4/L4,3) -> 0.298 | AB4: =ROUND((N4+U4+V4)/(L4+U4+V4+Z4),3) -> 0.394 | AC4: =ROUND(((N4-O4-P4-Q4)+2*O4+3*P4+4*Q4)/L4,3) -> 0.616 | AD4: =ROUND(AB4+AC4,3) -> 1.01 | AE4: =ROUND((('연도별 상수'!$N$46*(U4-W4))+('연도별 상수'!$O$46*V4)+('연도별 상수'!$P$46*(N4-O4-P4-Q4))+('연도별 상수'!$Q$46*O4)+('연도별 상수'!$R$46*P4)+('연도별 상수'!$S$46*Q4))/(L4+U4+V4-W4+Z4),3) -> 0.436 | AF4: ='연도별 상수'!AG$5 -> 0.22 | AG4: ='연도별 상수'!AH$5 -> -1 | AH4: ='연도별 상수'!$G$46 -> 0.919389 | AI4: 0 | AJ4: 0 | AK4: 0 | AL4: 0 | AM4: 0 | AN4: 0 | AO4: -3 | AP4: =K4 -> 371 | AQ4: 0
A5: 4 | B5: 박민우 | C5: ='연도별 상수'!AE$4 -> 2B | D5: NC | E5: ='연도별 상수'!$A$46 -> 2026 | F5: =ROUND(((H5)+(I5)+(AG5*K5/600)+(20*K5/600))/'연도별 상수'!$U$46,2) -> 3.18 | G5: =ROUND(100*(((((AE5-'리그 타자'!$B$46)/'연도별 상수'!$T$46)+'연도별 상수'!$W$46))+('연도별 상수'!$W$46*(1-AH5)))/'연도별 상수'!$W$46,1) -> 144.7 | H5: =ROUND((((AE5-'리그 타자'!$B$46)/'연도별 상수'!$T$46)*K5/AH5)+(S5*'연도별 상수'!$AB$46-T5*'연도별 상수'!$AC$46)-((S5+T5)*('연도별 상수'!$AD$46*0.2-(1-'연도별 상수'!$AD$46)*0.4))+0.05*(S5+O5+P5),1) -> 20.3 | I5: =ROUND((0.75*AO5)+(AF5*(J5/144)),1) -> 1.4 | J5: 78 | K5: 329 | L5: 273 | M5: 48 | N5: 92 | O5: 18 | P5: 0 | Q5: 5 | R5: 48 | S5: 26 | T5: 9 | U5: 46 | V5: 6 | W5: 2 | X5: 37 | Y5: 7 | Z5: 3 | AA5: =ROUND(N5/L5,3) -> 0.337 | AB5: =ROUND((N5+U5+V5)/(L5+U5+V5+Z5),3) -> 0.439 | AC5: =ROUND(((N5-O5-P5-Q5)+2*O5+3*P5+4*Q5)/L5,3) -> 0.458 | AD5: =ROUND(AB5+AC5,3) -> 0.897 | AE5: =ROUND((('연도별 상수'!$N$46*(U5-W5))+('연도별 상수'!$O$46*V5)+('연도별 상수'!$P$46*(N5-O5-P5-Q5))+('연도별 상수'!$Q$46*O5)+('연도별 상수'!$R$46*P5)+('연도별 상수'!$S$46*Q5))/(L5+U5+V5-W5+Z5),3) -> 0.413 | AF5: ='연도별 상수'!AG$4 -> 1.22 | AG5: ='연도별 상수'!AH$4 -> 3 | AH5: ='연도별 상수'!$J$46 -> 0.968492 | AI5: 0 | AJ5: 0 | AK5: 0 | AL5: 0 | AM5: 0 | AN5: 0 | AO5: 1 | AP5: =K5 -> 329 | AQ5: 0
A6: 5 | B6: 박성한 | C6: ='연도별 상수'!AE$6 -> SS | D6: SSG | E6: ='연도별 상수'!$A$46 -> 2026 | F6: =ROUND(((H6)+(I6)+(AG6*K6/600)+(20*K6/600))/'연도별 상수'!$U$46,2) -> 3.09 | G6: =ROUND(100*(((((AE6-'리그 타자'!$B$46)/'연도별 상수'!$T$46)+'연도별 상수'!$W$46))+('연도별 상수'!$W$46*(1-AH6)))/'연도별 상수'!$W$46,1) -> 140.9 | H6: =ROUND((((AE6-'리그 타자'!$B$46)/'연도별 상수'!$T$46)*K6/AH6)+(S6*'연도별 상수'!$AB$46-T6*'연도별 상수'!$AC$46)-((S6+T6)*('연도별 상수'!$AD$46*0.2-(1-'연도별 상수'!$AD$46)*0.4))+0.05*(S6+O6+P6),1) -> 19.3 | I6: =ROUND((0.75*AO6)+(AF6*(J6/144)),1) -> -2.8 | J6: 86 | K6: 374 | L6: 315 | M6: 57 | N6: 105 | O6: 20 | P6: 1 | Q6: 3 | R6: 39 | S6: 5 | T6: 2 | U6: 56 | V6: 1 | W6: 1 | X6: 45 | Y6: 2 | Z6: 2 | AA6: =ROUND(N6/L6,3) -> 0.333 | AB6: =ROUND((N6+U6+V6)/(L6+U6+V6+Z6),3) -> 0.433 | AC6: =ROUND(((N6-O6-P6-Q6)+2*O6+3*P6+4*Q6)/L6,3) -> 0.432 | AD6: =ROUND(AB6+AC6,3) -> 0.865 | AE6: =ROUND((('연도별 상수'!$N$46*(U6-W6))+('연도별 상수'!$O$46*V6)+('연도별 상수'!$P$46*(N6-O6-P6-Q6))+('연도별 상수'!$Q$46*O6)+('연도별 상수'!$R$46*P6)+('연도별 상수'!$S$46*Q6))/(L6+U6+V6-W6+Z6),3) -> 0.403 | AF6: ='연도별 상수'!AG$6 -> 2.77 | AG6: ='연도별 상수'!AH$6 -> 7 | AH6: ='연도별 상수'!$D$46 -> 0.943387 | AI6: 0 | AJ6: 0 | AK6: 0 | AL6: 0 | AM6: 0 | AN6: 0 | AO6: -6 | AP6: =K6 -> 374 | AQ6: 0
A7: 6 | B7: 한준수 | C7: ='연도별 상수'!AE$2 -> C | D7: KIA | E7: ='연도별 상수'!$A$46 -> 2026 | F7: =ROUND(((H7)+(I7)+(AG7*K7/600)+(20*K7/600))/'연도별 상수'!$U$46,2) -> 2.93 | G7: =ROUND(100*(((((AE7-'리그 타자'!$B$46)/'연도별 상수'!$T$46)+'연도별 상수'!$W$46))+('연도별 상수'!$W$46*(1-AH7)))/'연도별 상수'!$W$46,1) -> 153.9 | H7: =ROUND((((AE7-'리그 타자'!$B$46)/'연도별 상수'!$T$46)*K7/AH7)+(S7*'연도별 상수'!$AB$46-T7*'연도별 상수'!$AC$46)-((S7+T7)*('연도별 상수'!$AD$46*0.2-(1-'연도별 상수'!$AD$46)*0.4))+0.05*(S7+O7+P7),1) -> 17 | I7: =ROUND((0.75*AO7)+(AF7*(J7/144)),1) -> 1.9 | J7: 74 | K7: 256 | L7: 208 | M7: 29 | N7: 67 | O7: 17 | P7: 0 | Q7: 6 | R7: 26 | S7: 0 | T7: 1 | U7: 36 | V7: 6 | W7: 2 | X7: 37 | Y7: 7 | Z7: 2 | AA7: =ROUND(N7/L7,3) -> 0.322 | AB7: =ROUND((N7+U7+V7)/(L7+U7+V7+Z7),3) -> 0.433 | AC7: =ROUND(((N7-O7-P7-Q7)+2*O7+3*P7+4*Q7)/L7,3) -> 0.49 | AD7: =ROUND(AB7+AC7,3) -> 0.923 | AE7: =ROUND((('연도별 상수'!$N$46*(U7-W7))+('연도별 상수'!$O$46*V7)+('연도별 상수'!$P$46*(N7-O7-P7-Q7))+('연도별 상수'!$Q$46*O7)+('연도별 상수'!$R$46*P7)+('연도별 상수'!$S$46*Q7))/(L7+U7+V7-W7+Z7),3) -> 0.42 | AF7: ='연도별 상수'!AG$2 -> 5.22 | AG7: ='연도별 상수'!AH$2 -> 10 | AH7: ='연도별 상수'!$G$46 -> 0.919389 | AI7: 0 | AJ7: 0 | AK7: 0 | AL7: 0 | AM7: 0 | AN7: 0 | AO7: -1 | AP7: =K7 -> 256 | AQ7: 0
A8: 7 | B8: 최정 | C8: ='연도별 상수'!AE$5 -> 3B | D8: SSG | E8: ='연도별 상수'!$A$46 -> 2026 | F8: =ROUND(((H8)+(I8)+(AG8*K8/600)+(20*K8/600))/'연도별 상수'!$U$46,2) -> 2.89 | G8: =ROUND(100*(((((AE8-'리그 타자'!$B$46)/'연도별 상수'!$T$46)+'연도별 상수'!$W$46))+('연도별 상수'!$W$46*(1-AH8)))/'연도별 상수'!$W$46,1) -> 160.9 | H8: =ROUND((((AE8-'리그 타자'!$B$46)/'연도별 상수'!$T$46)*K8/AH8)+(S8*'연도별 상수'!$AB$46-T8*'연도별 상수'!$AC$46)-((S8+T8)*('연도별 상수'!$AD$46*0.2-(1-'연도별 상수'!$AD$46)*0.4))+0.05*(S8+O8+P8),1) -> 23.8 | I8: =ROUND((0.75*AO8)+(AF8*(J8/144)),1) -> -2.1 | J8: 70 | K8: 300 | L8: 251 | M8: 44 | N8: 77 | O8: 17 | P8: 1 | Q8: 19 | R8: 54 | S8: 3 | T8: 1 | U8: 37 | V8: 6 | W8: 5 | X8: 66 | Y8: 7 | Z8: 6 | AA8: =ROUND(N8/L8,3) -> 0.307 | AB8: =ROUND((N8+U8+V8)/(L8+U8+V8+Z8),3) -> 0.4 | AC8: =ROUND(((N8-O8-P8-Q8)+2*O8+3*P8+4*Q8)/L8,3) -> 0.61 | AD8: =ROUND(AB8+AC8,3) -> 1.01 | AE8: =ROUND((('연도별 상수'!$N$46*(U8-W8))+('연도별 상수'!$O$46*V8)+('연도별 상수'!$P$46*(N8-O8-P8-Q8))+('연도별 상수'!$Q$46*O8)+('연도별 상수'!$R$46*P8)+('연도별 상수'!$S$46*Q8))/(L8+U8+V8-W8+Z8),3) -> 0.435 | AF8: ='연도별 상수'!AG$5 -> 0.22 | AG8: ='연도별 상수'!AH$5 -> -1 | AH8: ='연도별 상수'!$D$46 -> 0.943387 | AI8: 0 | AJ8: 0 | AK8: 0 | AL8: 0 | AM8: 0 | AN8: 0 | AO8: -3 | AP8: =K8 -> 300 | AQ8: 0
A9: 8 | B9: 박찬호 | C9: ='연도별 상수'!AE$6 -> SS | D9: DOO | E9: ='연도별 상수'!$A$46 -> 2026 | F9: =ROUND(((H9)+(I9)+(AG9*K9/600)+(20*K9/600))/'연도별 상수'!$U$46,2) -> 2.64 | G9: =ROUND(100*(((((AE9-'리그 타자'!$B$46)/'연도별 상수'!$T$46)+'연도별 상수'!$W$46))+('연도별 상수'!$W$46*(1-AH9)))/'연도별 상수'!$W$46,1) -> 110.7 | H9: =ROUND((((AE9-'리그 타자'!$B$46)/'연도별 상수'!$T$46)*K9/AH9)+(S9*'연도별 상수'!$AB$46-T9*'연도별 상수'!$AC$46)-((S9+T9)*('연도별 상수'!$AD$46*0.2-(1-'연도별 상수'!$AD$46)*0.4))+0.05*(S9+O9+P9),1) -> 2.1 | I9: =ROUND((0.75*AO9)+(AF9*(J9/144)),1) -> 9.9 | J9: 87 | K9: 368 | L9: 320 | M9: 56 | N9: 90 | O9: 18 | P9: 2 | Q9: 4 | R9: 33 | S9: 20 | T9: 4 | U9: 36 | V9: 2 | W9: 1 | X9: 50 | Y9: 6 | Z9: 3 | AA9: =ROUND(N9/L9,3) -> 0.281 | AB9: =ROUND((N9+U9+V9)/(L9+U9+V9+Z9),3) -> 0.355 | AC9: =ROUND(((N9-O9-P9-Q9)+2*O9+3*P9+4*Q9)/L9,3) -> 0.388 | AD9: =ROUND(AB9+AC9,3) -> 0.743 | AE9: =ROUND((('연도별 상수'!$N$46*(U9-W9))+('연도별 상수'!$O$46*V9)+('연도별 상수'!$P$46*(N9-O9-P9-Q9))+('연도별 상수'!$Q$46*O9)+('연도별 상수'!$R$46*P9)+('연도별 상수'!$S$46*Q9))/(L9+U9+V9-W9+Z9),3) -> 0.343 | AF9: ='연도별 상수'!AG$6 -> 2.77 | AG9: ='연도별 상수'!AH$6 -> 7 | AH9: ='연도별 상수'!$B$46 -> 0.871842 | AI9: 0 | AJ9: 0 | AK9: 0 | AL9: 0 | AM9: 0 | AN9: 0 | AO9: 11 | AP9: =K9 -> 368 | AQ9: 0
A10: 9 | B10: 최원준 | C10: ='연도별 상수'!AE$9 -> RF | D10: KT | E10: ='연도별 상수'!$A$46 -> 2026 | F10: =ROUND(((H10)+(I10)+(AG10*K10/600)+(20*K10/600))/'연도별 상수'!$U$46,2) -> 2.37 | G10: =ROUND(100*(((((AE10-'리그 타자'!$B$46)/'연도별 상수'!$T$46)+'연도별 상수'!$W$46))+('연도별 상수'!$W$46*(1-AH10)))/'연도별 상수'!$W$46,1) -> 146.4 | H10: =ROUND((((AE10-'리그 타자'!$B$46)/'연도별 상수'!$T$46)*K10/AH10)+(S10*'연도별 상수'!$AB$46-T10*'연도별 상수'!$AC$46)-((S10+T10)*('연도별 상수'!$AD$46*0.2-(1-'연도별 상수'!$AD$46)*0.4))+0.05*(S10+O10+P10),1) -> 24.9 | I10: =ROUND((0.75*AO10)+(AF10*(J10/144)),1) -> -8.6 | J10: 79 | K10: 373 | L10: 320 | M10: 68 | N10: 116 | O10: 20 | P10: 3 | Q10: 7 | R10: 44 | S10: 16 | T10: 8 | U10: 41 | V10: 6 | W10: 0 | X10: 54 | Y10: 2 | Z10: 3 | AA10: =ROUND(N10/L10,3) -> 0.363 | AB10: =ROUND((N10+U10+V10)/(L10+U10+V10+Z10),3) -> 0.441 | AC10: =ROUND(((N10-O10-P10-Q10)+2*O10+3*P10+4*Q10)/L10,3) -> 0.509 | AD10: =ROUND(AB10+AC10,3) -> 0.95 | AE10: =ROUND((('연도별 상수'!$N$46*(U10-W10))+('연도별 상수'!$O$46*V10)+('연도별 상수'!$P$46*(N10-O10-P10-Q10))+('연도별 상수'!$Q$46*O10)+('연도별 상수'!$R$46*P10)+('연도별 상수'!$S$46*Q10))/(L10+U10+V10-W10+Z10),3) -> 0.432 | AF10: ='연도별 상수'!AG$9 -> -4.77 | AG10: ='연도별 상수'!AH$9 -> -5 | AH10: ='연도별 상수'!$E$46 -> 1.069855 | AI10: 0 | AJ10: 0 | AK10: 0 | AL10: 0 | AM10: 0 | AN10: 0 | AO10: -8 | AP10: =K10 -> 373 | AQ10: 0
A11: 10 | B11: 박해민 | C11: ='연도별 상수'!AE$8 -> CF | D11: LG | E11: ='연도별 상수'!$A$46 -> 2026 | F11: =ROUND(((H11)+(I11)+(AG11*K11/600)+(20*K11/600))/'연도별 상수'!$U$46,2) -> 2.42 | G11: =ROUND(100*(((((AE11-'리그 타자'!$B$46)/'연도별 상수'!$T$46)+'연도별 상수'!$W$46))+('연도별 상수'!$W$46*(1-AH11)))/'연도별 상수'!$W$46,1) -> 108.9 | H11: =ROUND((((AE11-'리그 타자'!$B$46)/'연도별 상수'!$T$46)*K11/AH11)+(S11*'연도별 상수'!$AB$46-T11*'연도별 상수'!$AC$46)-((S11+T11)*('연도별 상수'!$AD$46*0.2-(1-'연도별 상수'!$AD$46)*0.4))+0.05*(S11+O11+P11),1) -> 0.7 | I11: =ROUND((0.75*AO11)+(AF11*(J11/144)),1) -> 12.6 | J11: 85 | K11: 336 | L11: 282 | M11: 50 | N11: 82 | O11: 12 | P11: 0 | Q11: 3 | R11: 35 | S11: 24 | T11: 6 | U11: 27 | V11: 8 | W11: 0 | X11: 44 | Y11: 3 | Z11: 6 | AA11: =ROUND(N11/L11,3) -> 0.291 | AB11: =ROUND((N11+U11+V11)/(L11+U11+V11+Z11),3) -> 0.362 | AC11: =ROUND(((N11-O11-P11-Q11)+2*O11+3*P11+4*Q11)/L11,3) -> 0.365 | AD11: =ROUND(AB11+AC11,3) -> 0.727 | AE11: =ROUND((('연도별 상수'!$N$46*(U11-W11))+('연도별 상수'!$O$46*V11)+('연도별 상수'!$P$46*(N11-O11-P11-Q11))+('연도별 상수'!$Q$46*O11)+('연도별 상수'!$R$46*P11)+('연도별 상수'!$S$46*Q11))/(L11+U11+V11-W11+Z11),3) -> 0.34 | AF11: ='연도별 상수'!AG$8 -> 2.22 | AG11: ='연도별 상수'!AH$8 -> 3 | AH11: ='연도별 상수'!$B$46 -> 0.871842 | AI11: 0 | AJ11: 0 | AK11: 0 | AL11: 0 | AM11: 0 | AN11: 0 | AO11: 15 | AP11: =K11 -> 336 | AQ11: 0
A12: 11 | B12: 김지찬 | C12: ='연도별 상수'!AE$8 -> CF | D12: SAM | E12: ='연도별 상수'!$A$46 -> 2026 | F12: =ROUND(((H12)+(I12)+(AG12*K12/600)+(20*K12/600))/'연도별 상수'!$U$46,2) -> 2.43 | G12: =ROUND(100*(((((AE12-'리그 타자'!$B$46)/'연도별 상수'!$T$46)+'연도별 상수'!$W$46))+('연도별 상수'!$W$46*(1-AH12)))/'연도별 상수'!$W$46,1) -> 104.2 | H12: =ROUND((((AE12-'리그 타자'!$B$46)/'연도별 상수'!$T$46)*K12/AH12)+(S12*'연도별 상수'!$AB$46-T12*'연도별 상수'!$AC$46)-((S12+T12)*('연도별 상수'!$AD$46*0.2-(1-'연도별 상수'!$AD$46)*0.4))+0.05*(S12+O12+P12),1) -> 5.9 | I12: =ROUND((0.75*AO12)+(AF12*(J12/144)),1) -> 8 | J12: 83 | K12: 321 | L12: 266 | M12: 64 | N12: 83 | O12: 6 | P12: 2 | Q12: 0 | R12: 26 | S12: 15 | T12: 3 | U12: 42 | V12: 3 | W12: 1 | X12: 22 | Y12: 2 | Z12: 2 | AA12: =ROUND(N12/L12,3) -> 0.312 | AB12: =ROUND((N12+U12+V12)/(L12+U12+V12+Z12),3) -> 0.409 | AC12: =ROUND(((N12-O12-P12-Q12)+2*O12+3*P12+4*Q12)/L12,3) -> 0.35 | AD12: =ROUND(AB12+AC12,3) -> 0.759 | AE12: =ROUND((('연도별 상수'!$N$46*(U12-W12))+('연도별 상수'!$O$46*V12)+('연도별 상수'!$P$46*(N12-O12-P12-Q12))+('연도별 상수'!$Q$46*O12)+('연도별 상수'!$R$46*P12)+('연도별 상수'!$S$46*Q12))/(L12+U12+V12-W12+Z12),3) -> 0.362 | AF12: ='연도별 상수'!AG$8 -> 2.22 | AG12: ='연도별 상수'!AH$8 -> 3 | AH12: ='연도별 상수'!$H$46 -> 1.055356 | AI12: 0 | AJ12: 0 | AK12: 0 | AL12: 0 | AM12: 0 | AN12: 0 | AO12: 9 | AP12: =K12 -> 321 | AQ12: 0
A13: 12 | B13: 힐리어드 | C13: ='연도별 상수'!AE$8 -> CF | D13: KT | E13: ='연도별 상수'!$A$46 -> 2026 | F13: =ROUND(((H13)+(I13)+(AG13*K13/600)+(20*K13/600))/'연도별 상수'!$U$46,2) -> 2.21 | G13: =ROUND(100*(((((AE13-'리그 타자'!$B$46)/'연도별 상수'!$T$46)+'연도별 상수'!$W$46))+('연도별 상수'!$W$46*(1-AH13)))/'연도별 상수'!$W$46,1) -> 123.3 | H13: =ROUND((((AE13-'리그 타자'!$B$46)/'연도별 상수'!$T$46)*K13/AH13)+(S13*'연도별 상수'!$AB$46-T13*'연도별 상수'!$AC$46)-((S13+T13)*('연도별 상수'!$AD$46*0.2-(1-'연도별 상수'!$AD$46)*0.4))+0.05*(S13+O13+P13),1) -> 14.8 | I13: =ROUND((0.75*AO13)+(AF13*(J13/144)),1) -> -1.9 | J13: 83 | K13: 366 | L13: 326 | M13: 60 | N13: 95 | O13: 14 | P13: 3 | Q13: 20 | R13: 70 | S13: 7 | T13: 2 | U13: 36 | V13: 0 | W13: 1 | X13: 99 | Y13: 3 | Z13: 4 | AA13: =ROUND(N13/L13,3) -> 0.291 | AB13: =ROUND((N13+U13+V13)/(L13+U13+V13+Z13),3) -> 0.358 | AC13: =ROUND(((N13-O13-P13-Q13)+2*O13+3*P13+4*Q13)/L13,3) -> 0.537 | AD13: =ROUND(AB13+AC13,3) -> 0.895 | AE13: =ROUND((('연도별 상수'!$N$46*(U13-W13))+('연도별 상수'!$O$46*V13)+('연도별 상수'!$P$46*(N13-O13-P13-Q13))+('연도별 상수'!$Q$46*O13)+('연도별 상수'!$R$46*P13)+('연도별 상수'!$S$46*Q13))/(L13+U13+V13-W13+Z13),3) -> 0.395 | AF13: ='연도별 상수'!AG$8+'연도별 상수'!AG$7 -> -3.28 | AG13: ='연도별 상수'!AH$8+'연도별 상수'!AH$7 -> -2 | AH13: ='연도별 상수'!$E$46 -> 1.069855 | AI13: 0 | AJ13: 0 | AK13: 0 | AL13: 0 | AM13: 0 | AN13: 0 | AO13: 0 | AP13: =K13 -> 366 | AQ13: 1
A14: 13 | B14: 페라자 | C14: ='연도별 상수'!AE$9 -> RF | D14: HAN | E14: ='연도별 상수'!$A$46 -> 2026 | F14: =ROUND(((H14)+(I14)+(AG14*K14/600)+(20*K14/600))/'연도별 상수'!$U$46,2) -> 2 | G14: =ROUND(100*(((((AE14-'리그 타자'!$B$46)/'연도별 상수'!$T$46)+'연도별 상수'!$W$46))+('연도별 상수'!$W$46*(1-AH14)))/'연도별 상수'!$W$46,1) -> 135 | H14: =ROUND((((AE14-'리그 타자'!$B$46)/'연도별 상수'!$T$46)*K14/AH14)+(S14*'연도별 상수'!$AB$46-T14*'연도별 상수'!$AC$46)-((S14+T14)*('연도별 상수'!$AD$46*0.2-(1-'연도별 상수'!$AD$46)*0.4))+0.05*(S14+O14+P14),1) -> 22.6 | I14: =ROUND((0.75*AO14)+(AF14*(J14/144)),1) -> -10.2 | J14: 82 | K14: 368 | L14: 306 | M14: 69 | N14: 96 | O14: 22 | P14: 1 | Q14: 17 | R14: 53 | S14: 8 | T14: 3 | U14: 53 | V14: 3 | W14: 4 | X14: 71 | Y14: 6 | Z14: 4 | AA14: =ROUND(N14/L14,3) -> 0.314 | AB14: =ROUND((N14+U14+V14)/(L14+U14+V14+Z14),3) -> 0.415 | AC14: =ROUND(((N14-O14-P14-Q14)+2*O14+3*P14+4*Q14)/L14,3) -> 0.559 | AD14: =ROUND(AB14+AC14,3) -> 0.974 | AE14: =ROUND((('연도별 상수'!$N$46*(U14-W14))+('연도별 상수'!$O$46*V14)+('연도별 상수'!$P$46*(N14-O14-P14-Q14))+('연도별 상수'!$Q$46*O14)+('연도별 상수'!$R$46*P14)+('연도별 상수'!$S$46*Q14))/(L14+U14+V14-W14+Z14),3) -> 0.43 | AF14: ='연도별 상수'!AG$9 -> -4.77 | AG14: ='연도별 상수'!AH$9 -> -5 | AH14: ='연도별 상수'!$F$46 -> 1.170772 | AI14: 0 | AJ14: 0 | AK14: 0 | AL14: 0 | AM14: 0 | AN14: 0 | AO14: -10 | AP14: =K14 -> 368 | AQ14: 1
A15: 14 | B15: 노시환 | C15: ='연도별 상수'!AE$5 -> 3B | D15: HAN | E15: ='연도별 상수'!$A$46 -> 2026 | F15: =ROUND(((H15)+(I15)+(AG15*K15/600)+(20*K15/600))/'연도별 상수'!$U$46,2) -> 2.09 | G15: =ROUND(100*(((((AE15-'리그 타자'!$B$46)/'연도별 상수'!$T$46)+'연도별 상수'!$W$46))+('연도별 상수'!$W$46*(1-AH15)))/'연도별 상수'!$W$46,1) -> 99.5 | H15: =ROUND((((AE15-'리그 타자'!$B$46)/'연도별 상수'!$T$46)*K15/AH15)+(S15*'연도별 상수'!$AB$46-T15*'연도별 상수'!$AC$46)-((S15+T15)*('연도별 상수'!$AD$46*0.2-(1-'연도별 상수'!$AD$46)*0.4))+0.05*(S15+O15+P15),1) -> 6.4 | I15: =ROUND((0.75*AO15)+(AF15*(J15/144)),1) -> 5.4 | J15: 75 | K15: 340 | L15: 297 | M15: 59 | N15: 78 | O15: 13 | P15: 1 | Q15: 17 | R15: 56 | S15: 2 | T15: 2 | U15: 32 | V15: 7 | W15: 0 | X15: 93 | Y15: 8 | Z15: 3 | AA15: =ROUND(N15/L15,3) -> 0.263 | AB15: =ROUND((N15+U15+V15)/(L15+U15+V15+Z15),3) -> 0.345 | AC15: =ROUND(((N15-O15-P15-Q15)+2*O15+3*P15+4*Q15)/L15,3) -> 0.485 | AD15: =ROUND(AB15+AC15,3) -> 0.83 | AE15: =ROUND((('연도별 상수'!$N$46*(U15-W15))+('연도별 상수'!$O$46*V15)+('연도별 상수'!$P$46*(N15-O15-P15-Q15))+('연도별 상수'!$Q$46*O15)+('연도별 상수'!$R$46*P15)+('연도별 상수'!$S$46*Q15))/(L15+U15+V15-W15+Z15),3) -> 0.373 | AF15: ='연도별 상수'!AG$5 -> 0.22 | AG15: ='연도별 상수'!AH$5 -> -1 | AH15: ='연도별 상수'!$F$46 -> 1.170772 | AI15: 0 | AJ15: 0 | AK15: 0 | AL15: 0 | AM15: 0 | AN15: 0 | AO15: 7 | AP15: =K15 -> 340 | AQ15: 0
A16: 15 | B16: 허인서 | C16: ='연도별 상수'!AE$2 -> C | D16: HAN | E16: ='연도별 상수'!$A$46 -> 2026 | F16: =ROUND(((H16)+(I16)+(AG16*K16/600)+(20*K16/600))/'연도별 상수'!$U$46,2) -> 2.06 | G16: =ROUND(100*(((((AE16-'리그 타자'!$B$46)/'연도별 상수'!$T$46)+'연도별 상수'!$W$46))+('연도별 상수'!$W$46*(1-AH16)))/'연도별 상수'!$W$46,1) -> 108.2 | H16: =ROUND((((AE16-'리그 타자'!$B$46)/'연도별 상수'!$T$46)*K16/AH16)+(S16*'연도별 상수'!$AB$46-T16*'연도별 상수'!$AC$46)-((S16+T16)*('연도별 상수'!$AD$46*0.2-(1-'연도별 상수'!$AD$46)*0.4))+0.05*(S16+O16+P16),1) -> 6.7 | I16: =ROUND((0.75*AO16)+(AF16*(J16/144)),1) -> 3.4 | J16: 73 | K16: 244 | L16: 212 | M16: 39 | N16: 62 | O16: 7 | P16: 0 | Q16: 12 | R16: 45 | S16: 0 | T16: 1 | U16: 21 | V16: 6 | W16: 2 | X16: 73 | Y16: 1 | Z16: 2 | AA16: =ROUND(N16/L16,3) -> 0.292 | AB16: =ROUND((N16+U16+V16)/(L16+U16+V16+Z16),3) -> 0.369 | AC16: =ROUND(((N16-O16-P16-Q16)+2*O16+3*P16+4*Q16)/L16,3) -> 0.495 | AD16: =ROUND(AB16+AC16,3) -> 0.864 | AE16: =ROUND((('연도별 상수'!$N$46*(U16-W16))+('연도별 상수'!$O$46*V16)+('연도별 상수'!$P$46*(N16-O16-P16-Q16))+('연도별 상수'!$Q$46*O16)+('연도별 상수'!$R$46*P16)+('연도별 상수'!$S$46*Q16))/(L16+U16+V16-W16+Z16),3) -> 0.387 | AF16: ='연도별 상수'!AG$2 -> 5.22 | AG16: ='연도별 상수'!AH$2 -> 10 | AH16: ='연도별 상수'!$F$46 -> 1.170772 | AI16: 0 | AJ16: 0 | AK16: 0 | AL16: 0 | AM16: 0 | AN16: 0 | AO16: 1 | AP16: =K16 -> 244 | AQ16: 0
A17: 16 | B17: 김호령 | C17: ='연도별 상수'!AE$8 -> CF | D17: KIA | E17: ='연도별 상수'!$A$46 -> 2026 | F17: =ROUND(((H17)+(I17)+(AG17*K17/600)+(20*K17/600))/'연도별 상수'!$U$46,2) -> 2.06 | G17: =ROUND(100*(((((AE17-'리그 타자'!$B$46)/'연도별 상수'!$T$46)+'연도별 상수'!$W$46))+('연도별 상수'!$W$46*(1-AH17)))/'연도별 상수'!$W$46,1) -> 107.8 | H17: =ROUND((((AE17-'리그 타자'!$B$46)/'연도별 상수'!$T$46)*K17/AH17)+(S17*'연도별 상수'!$AB$46-T17*'연도별 상수'!$AC$46)-((S17+T17)*('연도별 상수'!$AD$46*0.2-(1-'연도별 상수'!$AD$46)*0.4))+0.05*(S17+O17+P17),1) -> 1 | I17: =ROUND((0.75*AO17)+(AF17*(J17/144)),1) -> 7.3 | J17: 85 | K17: 363 | L17: 329 | M17: 50 | N17: 92 | O17: 22 | P17: 1 | Q17: 11 | R17: 46 | S17: 9 | T17: 4 | U17: 20 | V17: 3 | W17: 1 | X17: 95 | Y17: 6 | Z17: 5 | AA17: =ROUND(N17/L17,3) -> 0.28 | AB17: =ROUND((N17+U17+V17)/(L17+U17+V17+Z17),3) -> 0.322 | AC17: =ROUND(((N17-O17-P17-Q17)+2*O17+3*P17+4*Q17)/L17,3) -> 0.453 | AD17: =ROUND(AB17+AC17,3) -> 0.775 | AE17: =ROUND((('연도별 상수'!$N$46*(U17-W17))+('연도별 상수'!$O$46*V17)+('연도별 상수'!$P$46*(N17-O17-P17-Q17))+('연도별 상수'!$Q$46*O17)+('연도별 상수'!$R$46*P17)+('연도별 상수'!$S$46*Q17))/(L17+U17+V17-W17+Z17),3) -> 0.346 | AF17: ='연도별 상수'!AG$8 -> 2.22 | AG17: ='연도별 상수'!AH$8 -> 3 | AH17: ='연도별 상수'!$G$46 -> 0.919389 | AI17: 0 | AJ17: 0 | AK17: 0 | AL17: 0 | AM17: 0 | AN17: 0 | AO17: 8 | AP17: =K17 -> 363 | AQ17: 0
A18: 17 | B18: 류지혁 | C18: ='연도별 상수'!AE$4 -> 2B | D18: SAM | E18: ='연도별 상수'!$A$46 -> 2026 | F18: =ROUND(((H18)+(I18)+(AG18*K18/600)+(20*K18/600))/'연도별 상수'!$U$46,2) -> 2.02 | G18: =ROUND(100*(((((AE18-'리그 타자'!$B$46)/'연도별 상수'!$T$46)+'연도별 상수'!$W$46))+('연도별 상수'!$W$46*(1-AH18)))/'연도별 상수'!$W$46,1) -> 110.4 | H18: =ROUND((((AE18-'리그 타자'!$B$46)/'연도별 상수'!$T$46)*K18/AH18)+(S18*'연도별 상수'!$AB$46-T18*'연도별 상수'!$AC$46)-((S18+T18)*('연도별 상수'!$AD$46*0.2-(1-'연도별 상수'!$AD$46)*0.4))+0.05*(S18+O18+P18),1) -> 10.3 | I18: =ROUND((0.75*AO18)+(AF18*(J18/144)),1) -> -0.8 | J18: 81 | K18: 322 | L18: 271 | M18: 41 | N18: 79 | O18: 12 | P18: 4 | Q18: 5 | R18: 47 | S18: 18 | T18: 1 | U18: 38 | V18: 6 | W18: 1 | X18: 46 | Y18: 5 | Z18: 3 | AA18: =ROUND(N18/L18,3) -> 0.292 | AB18: =ROUND((N18+U18+V18)/(L18+U18+V18+Z18),3) -> 0.387 | AC18: =ROUND(((N18-O18-P18-Q18)+2*O18+3*P18+4*Q18)/L18,3) -> 0.421 | AD18: =ROUND(AB18+AC18,3) -> 0.808 | AE18: =ROUND((('연도별 상수'!$N$46*(U18-W18))+('연도별 상수'!$O$46*V18)+('연도별 상수'!$P$46*(N18-O18-P18-Q18))+('연도별 상수'!$Q$46*O18)+('연도별 상수'!$R$46*P18)+('연도별 상수'!$S$46*Q18))/(L18+U18+V18-W18+Z18),3) -> 0.372 | AF18: ='연도별 상수'!AG$4 -> 1.22 | AG18: ='연도별 상수'!AH$4 -> 3 | AH18: ='연도별 상수'!$H$46 -> 1.055356 | AI18: 0 | AJ18: 0 | AK18: 0 | AL18: 0 | AM18: 0 | AN18: 0 | AO18: -2 | AP18: =K18 -> 322 | AQ18: 0
A19: 18 | B19: 박준순 | C19: ='연도별 상수'!AE$4 -> 2B | D19: DOO | E19: ='연도별 상수'!$A$46 -> 2026 | F19: =ROUND(((H19)+(I19)+(AG19*K19/600)+(20*K19/600))/'연도별 상수'!$U$46,2) -> 2.13 | G19: =ROUND(100*(((((AE19-'리그 타자'!$B$46)/'연도별 상수'!$T$46)+'연도별 상수'!$W$46))+('연도별 상수'!$W$46*(1-AH19)))/'연도별 상수'!$W$46,1) -> 161.2 | H19: =ROUND((((AE19-'리그 타자'!$B$46)/'연도별 상수'!$T$46)*K19/AH19)+(S19*'연도별 상수'!$AB$46-T19*'연도별 상수'!$AC$46)-((S19+T19)*('연도별 상수'!$AD$46*0.2-(1-'연도별 상수'!$AD$46)*0.4))+0.05*(S19+O19+P19),1) -> 17.3 | I19: =ROUND((0.75*AO19)+(AF19*(J19/144)),1) -> -3.3 | J19: 54 | K19: 234 | L19: 217 | M19: 28 | N19: 73 | O19: 9 | P19: 5 | Q19: 11 | R19: 39 | S19: 1 | T19: 1 | U19: 12 | V19: 4 | W19: 0 | X19: 46 | Y19: 7 | Z19: 1 | AA19: =ROUND(N19/L19,3) -> 0.336 | AB19: =ROUND((N19+U19+V19)/(L19+U19+V19+Z19),3) -> 0.38 | AC19: =ROUND(((N19-O19-P19-Q19)+2*O19+3*P19+4*Q19)/L19,3) -> 0.576 | AD19: =ROUND(AB19+AC19,3) -> 0.956 | AE19: =ROUND((('연도별 상수'!$N$46*(U19-W19))+('연도별 상수'!$O$46*V19)+('연도별 상수'!$P$46*(N19-O19-P19-Q19))+('연도별 상수'!$Q$46*O19)+('연도별 상수'!$R$46*P19)+('연도별 상수'!$S$46*Q19))/(L19+U19+V19-W19+Z19),3) -> 0.424 | AF19: ='연도별 상수'!AG$4 -> 1.22 | AG19: ='연도별 상수'!AH$4 -> 3 | AH19: ='연도별 상수'!$B$46 -> 0.871842 | AI19: 0 | AJ19: 0 | AK19: 0 | AL19: 0 | AM19: 0 | AN19: 0 | AO19: -5 | AP19: =K19 -> 234 | AQ19: 0
A20: 19 | B20: 최지훈 | C20: ='연도별 상수'!AE$8 -> CF | D20: SSG | E20: ='연도별 상수'!$A$46 -> 2026 | F20: =ROUND(((H20)+(I20)+(AG20*K20/600)+(20*K20/600))/'연도별 상수'!$U$46,2) -> 1.79 | G20: =ROUND(100*(((((AE20-'리그 타자'!$B$46)/'연도별 상수'!$T$46)+'연도별 상수'!$W$46))+('연도별 상수'!$W$46*(1-AH20)))/'연도별 상수'!$W$46,1) -> 89.9 | H20: =ROUND((((AE20-'리그 타자'!$B$46)/'연도별 상수'!$T$46)*K20/AH20)+(S20*'연도별 상수'!$AB$46-T20*'연도별 상수'!$AC$46)-((S20+T20)*('연도별 상수'!$AD$46*0.2-(1-'연도별 상수'!$AD$46)*0.4))+0.05*(S20+O20+P20),1) -> -4.2 | I20: =ROUND((0.75*AO20)+(AF20*(J20/144)),1) -> 10.3 | J20: 84 | K20: 346 | L20: 315 | M20: 45 | N20: 76 | O20: 15 | P20: 6 | Q20: 10 | R20: 38 | S20: 11 | T20: 0 | U20: 22 | V20: 3 | W20: 0 | X20: 48 | Y20: 5 | Z20: 4 | AA20: =ROUND(N20/L20,3) -> 0.241 | AB20: =ROUND((N20+U20+V20)/(L20+U20+V20+Z20),3) -> 0.294 | AC20: =ROUND(((N20-O20-P20-Q20)+2*O20+3*P20+4*Q20)/L20,3) -> 0.422 | AD20: =ROUND(AB20+AC20,3) -> 0.716 | AE20: =ROUND((('연도별 상수'!$N$46*(U20-W20))+('연도별 상수'!$O$46*V20)+('연도별 상수'!$P$46*(N20-O20-P20-Q20))+('연도별 상수'!$Q$46*O20)+('연도별 상수'!$R$46*P20)+('연도별 상수'!$S$46*Q20))/(L20+U20+V20-W20+Z20),3) -> 0.321 | AF20: ='연도별 상수'!AG$8 -> 2.22 | AG20: ='연도별 상수'!AH$8 -> 3 | AH20: ='연도별 상수'!$D$46 -> 0.943387 | AI20: 0 | AJ20: 0 | AK20: 0 | AL20: 0 | AM20: 0 | AN20: 0 | AO20: 12 | AP20: =K20 -> 346 | AQ20: 0
A21: 20 | B21: 송찬의 | C21: ='연도별 상수'!AE$7 -> LF | D21: LG | E21: ='연도별 상수'!$A$46 -> 2026 | F21: =ROUND(((H21)+(I21)+(AG21*K21/600)+(20*K21/600))/'연도별 상수'!$U$46,2) -> 1.98 | G21: =ROUND(100*(((((AE21-'리그 타자'!$B$46)/'연도별 상수'!$T$46)+'연도별 상수'!$W$46))+('연도별 상수'!$W$46*(1-AH21)))/'연도별 상수'!$W$46,1) -> 158.7 | H21: =ROUND((((AE21-'리그 타자'!$B$46)/'연도별 상수'!$T$46)*K21/AH21)+(S21*'연도별 상수'!$AB$46-T21*'연도별 상수'!$AC$46)-((S21+T21)*('연도별 상수'!$AD$46*0.2-(1-'연도별 상수'!$AD$46)*0.4))+0.05*(S21+O21+P21),1) -> 16.1 | I21: =ROUND((0.75*AO21)+(AF21*(J21/144)),1) -> -0.2 | J21: 63 | K21: 219 | L21: 188 | M21: 39 | N21: 56 | O21: 19 | P21: 1 | Q21: 8 | R21: 33 | S21: 1 | T21: 0 | U21: 21 | V21: 10 | W21: 0 | X21: 53 | Y21: 7 | Z21: 0 | AA21: =ROUND(N21/L21,3) -> 0.298 | AB21: =ROUND((N21+U21+V21)/(L21+U21+V21+Z21),3) -> 0.397 | AC21: =ROUND(((N21-O21-P21-Q21)+2*O21+3*P21+4*Q21)/L21,3) -> 0.537 | AD21: =ROUND(AB21+AC21,3) -> 0.934 | AE21: =ROUND((('연도별 상수'!$N$46*(U21-W21))+('연도별 상수'!$O$46*V21)+('연도별 상수'!$P$46*(N21-O21-P21-Q21))+('연도별 상수'!$Q$46*O21)+('연도별 상수'!$R$46*P21)+('연도별 상수'!$S$46*Q21))/(L21+U21+V21-W21+Z21),3) -> 0.42 | AF21: ='연도별 상수'!AG$7 -> -5.5 | AG21: ='연도별 상수'!AH$7 -> -5 | AH21: ='연도별 상수'!$B$46 -> 0.871842 | AI21: 0 | AJ21: 0 | AK21: 0 | AL21: 0 | AM21: 0 | AN21: 0 | AO21: 3 | AP21: =K21 -> 219 | AQ21: 0
A22: 21 | B22: 박동원 | C22: ='연도별 상수'!AE$2 -> C | D22: LG | E22: ='연도별 상수'!$A$46 -> 2026 | F22: =ROUND(((H22)+(I22)+(AG22*K22/600)+(20*K22/600))/'연도별 상수'!$U$46,2) -> 1.77 | G22: =ROUND(100*(((((AE22-'리그 타자'!$B$46)/'연도별 상수'!$T$46)+'연도별 상수'!$W$46))+('연도별 상수'!$W$46*(1-AH22)))/'연도별 상수'!$W$46,1) -> 117 | H22: =ROUND((((AE22-'리그 타자'!$B$46)/'연도별 상수'!$T$46)*K22/AH22)+(S22*'연도별 상수'!$AB$46-T22*'연도별 상수'!$AC$46)-((S22+T22)*('연도별 상수'!$AD$46*0.2-(1-'연도별 상수'!$AD$46)*0.4))+0.05*(S22+O22+P22),1) -> 1.5 | I22: =ROUND((0.75*AO22)+(AF22*(J22/144)),1) -> 4.3 | J22: 76 | K22: 267 | L22: 217 | M22: 34 | N22: 52 | O22: 11 | P22: 0 | Q22: 9 | R22: 38 | S22: 1 | T22: 2 | U22: 37 | V22: 4 | W22: 2 | X22: 66 | Y22: 9 | Z22: 3 | AA22: =ROUND(N22/L22,3) -> 0.24 | AB22: =ROUND((N22+U22+V22)/(L22+U22+V22+Z22),3) -> 0.356 | AC22: =ROUND(((N22-O22-P22-Q22)+2*O22+3*P22+4*Q22)/L22,3) -> 0.415 | AD22: =ROUND(AB22+AC22,3) -> 0.771 | AE22: =ROUND((('연도별 상수'!$N$46*(U22-W22))+('연도별 상수'!$O$46*V22)+('연도별 상수'!$P$46*(N22-O22-P22-Q22))+('연도별 상수'!$Q$46*O22)+('연도별 상수'!$R$46*P22)+('연도별 상수'!$S$46*Q22))/(L22+U22+V22-W22+Z22),3) -> 0.353 | AF22: ='연도별 상수'!AG$2 -> 5.22 | AG22: ='연도별 상수'!AH$2 -> 10 | AH22: ='연도별 상수'!$B$46 -> 0.871842 | AI22: 0 | AJ22: 0 | AK22: 0 | AL22: 0 | AM22: 0 | AN22: 0 | AO22: 2 | AP22: =K22 -> 267 | AQ22: 0
A23: 22 | B23: 양의지 | C23: ='연도별 상수'!AE$2 -> C | D23: DOO | E23: ='연도별 상수'!$A$46 -> 2026 | F23: =ROUND(((H23)+(I23)+(AG23*K23/600)+(20*K23/600))/'연도별 상수'!$U$46,2) -> 1.68 | G23: =ROUND(100*(((((AE23-'리그 타자'!$B$46)/'연도별 상수'!$T$46)+'연도별 상수'!$W$46))+('연도별 상수'!$W$46*(1-AH23)))/'연도별 상수'!$W$46,1) -> 111.4 | H23: =ROUND((((AE23-'리그 타자'!$B$46)/'연도별 상수'!$T$46)*K23/AH23)+(S23*'연도별 상수'!$AB$46-T23*'연도별 상수'!$AC$46)-((S23+T23)*('연도별 상수'!$AD$46*0.2-(1-'연도별 상수'!$AD$46)*0.4))+0.05*(S23+O23+P23),1) -> 0 | I23: =ROUND((0.75*AO23)+(AF23*(J23/144)),1) -> 1.5 | J23: 84 | K23: 333 | L23: 281 | M23: 27 | N23: 71 | O23: 11 | P23: 0 | Q23: 11 | R23: 43 | S23: 1 | T23: 0 | U23: 27 | V23: 16 | W23: 0 | X23: 37 | Y23: 8 | Z23: 9 | AA23: =ROUND(N23/L23,3) -> 0.253 | AB23: =ROUND((N23+U23+V23)/(L23+U23+V23+Z23),3) -> 0.342 | AC23: =ROUND(((N23-O23-P23-Q23)+2*O23+3*P23+4*Q23)/L23,3) -> 0.409 | AD23: =ROUND(AB23+AC23,3) -> 0.751 | AE23: =ROUND((('연도별 상수'!$N$46*(U23-W23))+('연도별 상수'!$O$46*V23)+('연도별 상수'!$P$46*(N23-O23-P23-Q23))+('연도별 상수'!$Q$46*O23)+('연도별 상수'!$R$46*P23)+('연도별 상수'!$S$46*Q23))/(L23+U23+V23-W23+Z23),3) -> 0.344 | AF23: ='연도별 상수'!AG$2 -> 5.22 | AG23: ='연도별 상수'!AH$2 -> 10 | AH23: ='연도별 상수'!$B$46 -> 0.871842 | AI23: 0 | AJ23: 0 | AK23: 0 | AL23: 0 | AM23: 0 | AN23: 0 | AO23: -2 | AP23: =K23 -> 333 | AQ23: 0
A24: 23 | B24: 정수빈 | C24: ='연도별 상수'!AE$8 -> CF | D24: DOO | E24: ='연도별 상수'!$A$46 -> 2026 | F24: =ROUND(((H24)+(I24)+(AG24*K24/600)+(20*K24/600))/'연도별 상수'!$U$46,2) -> 1.66 | G24: =ROUND(100*(((((AE24-'리그 타자'!$B$46)/'연도별 상수'!$T$46)+'연도별 상수'!$W$46))+('연도별 상수'!$W$46*(1-AH24)))/'연도별 상수'!$W$46,1) -> 107.6 | H24: =ROUND((((AE24-'리그 타자'!$B$46)/'연도별 상수'!$T$46)*K24/AH24)+(S24*'연도별 상수'!$AB$46-T24*'연도별 상수'!$AC$46)-((S24+T24)*('연도별 상수'!$AD$46*0.2-(1-'연도별 상수'!$AD$46)*0.4))+0.05*(S24+O24+P24),1) -> -1 | I24: =ROUND((0.75*AO24)+(AF24*(J24/144)),1) -> 5.8 | J24: 85 | K24: 342 | L24: 297 | M24: 45 | N24: 79 | O24: 8 | P24: 4 | Q24: 6 | R24: 32 | S24: 14 | T24: 4 | U24: 34 | V24: 4 | W24: 1 | X24: 49 | Y24: 4 | Z24: 1 | AA24: =ROUND(N24/L24,3) -> 0.266 | AB24: =ROUND((N24+U24+V24)/(L24+U24+V24+Z24),3) -> 0.348 | AC24: =ROUND(((N24-O24-P24-Q24)+2*O24+3*P24+4*Q24)/L24,3) -> 0.38 | AD24: =ROUND(AB24+AC24,3) -> 0.728 | AE24: =ROUND((('연도별 상수'!$N$46*(U24-W24))+('연도별 상수'!$O$46*V24)+('연도별 상수'!$P$46*(N24-O24-P24-Q24))+('연도별 상수'!$Q$46*O24)+('연도별 상수'!$R$46*P24)+('연도별 상수'!$S$46*Q24))/(L24+U24+V24-W24+Z24),3) -> 0.338 | AF24: ='연도별 상수'!AG$8 -> 2.22 | AG24: ='연도별 상수'!AH$8 -> 3 | AH24: ='연도별 상수'!$B$46 -> 0.871842 | AI24: 0 | AJ24: 0 | AK24: 0 | AL24: 0 | AM24: 0 | AN24: 0 | AO24: 6 | AP24: =K24 -> 342 | AQ24: 0
A25: 24 | B25: 강백호 | C25: ='연도별 상수'!AE$10 -> DH | D25: HAN | E25: ='연도별 상수'!$A$46 -> 2026 | F25: =ROUND(((H25)+(I25)+(AG25*K25/600)+(20*K25/600))/'연도별 상수'!$U$46,2) -> 1.43 | G25: =ROUND(100*(((((AE25-'리그 타자'!$B$46)/'연도별 상수'!$T$46)+'연도별 상수'!$W$46))+('연도별 상수'!$W$46*(1-AH25)))/'연도별 상수'!$W$46,1) -> 134.4 | H25: =ROUND((((AE25-'리그 타자'!$B$46)/'연도별 상수'!$T$46)*K25/AH25)+(S25*'연도별 상수'!$AB$46-T25*'연도별 상수'!$AC$46)-((S25+T25)*('연도별 상수'!$AD$46*0.2-(1-'연도별 상수'!$AD$46)*0.4))+0.05*(S25+O25+P25),1) -> 19.4 | I25: =ROUND((0.75*AO25)+(AF25*(J25/144)),1) -> -6.8 | J25: 78 | K25: 341 | L25: 300 | M25: 50 | N25: 94 | O25: 17 | P25: 0 | Q25: 23 | R25: 85 | S25: 0 | T25: 2 | U25: 36 | V25: 1 | W25: 3 | X25: 68 | Y25: 6 | Z25: 4 | AA25: =ROUND(N25/L25,3) -> 0.313 | AB25: =ROUND((N25+U25+V25)/(L25+U25+V25+Z25),3) -> 0.384 | AC25: =ROUND(((N25-O25-P25-Q25)+2*O25+3*P25+4*Q25)/L25,3) -> 0.6 | AD25: =ROUND(AB25+AC25,3) -> 0.984 | AE25: =ROUND((('연도별 상수'!$N$46*(U25-W25))+('연도별 상수'!$O$46*V25)+('연도별 상수'!$P$46*(N25-O25-P25-Q25))+('연도별 상수'!$Q$46*O25)+('연도별 상수'!$R$46*P25)+('연도별 상수'!$S$46*Q25))/(L25+U25+V25-W25+Z25),3) -> 0.429 | AF25: ='연도별 상수'!AG$10 -> -12.5 | AG25: ='연도별 상수'!AH$10 -> -15 | AH25: ='연도별 상수'!$F$46 -> 1.170772 | AI25: 0 | AJ25: 0 | AK25: 0 | AL25: 0 | AM25: 0 | AN25: 0 | AO25: 0 | AP25: =K25 -> 341 | AQ25: 0
A26: 25 | B26: 나성범 | C26: ='연도별 상수'!AE$9 -> RF | D26: KIA | E26: ='연도별 상수'!$A$46 -> 2026 | F26: =ROUND(((H26)+(I26)+(AG26*K26/600)+(20*K26/600))/'연도별 상수'!$U$46,2) -> 1.77 | G26: =ROUND(100*(((((AE26-'리그 타자'!$B$46)/'연도별 상수'!$T$46)+'연도별 상수'!$W$46))+('연도별 상수'!$W$46*(1-AH26)))/'연도별 상수'!$W$46,1) -> 146.5 | H26: =ROUND((((AE26-'리그 타자'!$B$46)/'연도별 상수'!$T$46)*K26/AH26)+(S26*'연도별 상수'!$AB$46-T26*'연도별 상수'!$AC$46)-((S26+T26)*('연도별 상수'!$AD$46*0.2-(1-'연도별 상수'!$AD$46)*0.4))+0.05*(S26+O26+P26),1) -> 18.8 | I26: =ROUND((0.75*AO26)+(AF26*(J26/144)),1) -> -8 | J26: 82 | K26: 331 | L26: 288 | M26: 47 | N26: 85 | O26: 17 | P26: 0 | Q26: 17 | R26: 49 | S26: 0 | T26: 0 | U26: 36 | V26: 5 | W26: 0 | X26: 87 | Y26: 5 | Z26: 2 | AA26: =ROUND(N26/L26,3) -> 0.295 | AB26: =ROUND((N26+U26+V26)/(L26+U26+V26+Z26),3) -> 0.381 | AC26: =ROUND(((N26-O26-P26-Q26)+2*O26+3*P26+4*Q26)/L26,3) -> 0.531 | AD26: =ROUND(AB26+AC26,3) -> 0.912 | AE26: =ROUND((('연도별 상수'!$N$46*(U26-W26))+('연도별 상수'!$O$46*V26)+('연도별 상수'!$P$46*(N26-O26-P26-Q26))+('연도별 상수'!$Q$46*O26)+('연도별 상수'!$R$46*P26)+('연도별 상수'!$S$46*Q26))/(L26+U26+V26-W26+Z26),3) -> 0.408 | AF26: ='연도별 상수'!AG$9 -> -4.77 | AG26: ='연도별 상수'!AH$9 -> -5 | AH26: ='연도별 상수'!$G$46 -> 0.919389 | AI26: 0 | AJ26: 0 | AK26: 0 | AL26: 0 | AM26: 0 | AN26: 0 | AO26: -7 | AP26: =K26 -> 331 | AQ26: 0
A27: 26 | B27: 레이예스 | C27: ='연도별 상수'!AE$7 -> LF | D27: LOT | E27: ='연도별 상수'!$A$46 -> 2026 | F27: =ROUND(((H27)+(I27)+(AG27*K27/600)+(20*K27/600))/'연도별 상수'!$U$46,2) -> 1.49 | G27: =ROUND(100*(((((AE27-'리그 타자'!$B$46)/'연도별 상수'!$T$46)+'연도별 상수'!$W$46))+('연도별 상수'!$W$46*(1-AH27)))/'연도별 상수'!$W$46,1) -> 122 | H27: =ROUND((((AE27-'리그 타자'!$B$46)/'연도별 상수'!$T$46)*K27/AH27)+(S27*'연도별 상수'!$AB$46-T27*'연도별 상수'!$AC$46)-((S27+T27)*('연도별 상수'!$AD$46*0.2-(1-'연도별 상수'!$AD$46)*0.4))+0.05*(S27+O27+P27),1) -> 16.7 | I27: =ROUND((0.75*AO27)+(AF27*(J27/144)),1) -> -10 | J27: 85 | K27: 374 | L27: 336 | M27: 43 | N27: 117 | O27: 19 | P27: 1 | Q27: 11 | R27: 61 | S27: 1 | T27: 1 | U27: 33 | V27: 2 | W27: 7 | X27: 40 | Y27: 5 | Z27: 3 | AA27: =ROUND(N27/L27,3) -> 0.348 | AB27: =ROUND((N27+U27+V27)/(L27+U27+V27+Z27),3) -> 0.406 | AC27: =ROUND(((N27-O27-P27-Q27)+2*O27+3*P27+4*Q27)/L27,3) -> 0.509 | AD27: =ROUND(AB27+AC27,3) -> 0.915 | AE27: =ROUND((('연도별 상수'!$N$46*(U27-W27))+('연도별 상수'!$O$46*V27)+('연도별 상수'!$P$46*(N27-O27-P27-Q27))+('연도별 상수'!$Q$46*O27)+('연도별 상수'!$R$46*P27)+('연도별 상수'!$S$46*Q27))/(L27+U27+V27-W27+Z27),3) -> 0.408 | AF27: ='연도별 상수'!AG$7 -> -5.5 | AG27: ='연도별 상수'!AH$7 -> -5 | AH27: ='연도별 상수'!$I$46 -> 1.163773 | AI27: 0 | AJ27: 0 | AK27: 0 | AL27: 0 | AM27: 0 | AN27: 0 | AO27: -9 | AP27: =K27 -> 374 | AQ27: 1
A28: 27 | B28: 구자욱 | C28: ='연도별 상수'!AE$7 -> LF | D28: SAM | E28: ='연도별 상수'!$A$46 -> 2026 | F28: =ROUND(((H28)+(I28)+(AG28*K28/600)+(20*K28/600))/'연도별 상수'!$U$46,2) -> 1.65 | G28: =ROUND(100*(((((AE28-'리그 타자'!$B$46)/'연도별 상수'!$T$46)+'연도별 상수'!$W$46))+('연도별 상수'!$W$46*(1-AH28)))/'연도별 상수'!$W$46,1) -> 141 | H28: =ROUND((((AE28-'리그 타자'!$B$46)/'연도별 상수'!$T$46)*K28/AH28)+(S28*'연도별 상수'!$AB$46-T28*'연도별 상수'!$AC$46)-((S28+T28)*('연도별 상수'!$AD$46*0.2-(1-'연도별 상수'!$AD$46)*0.4))+0.05*(S28+O28+P28),1) -> 17.6 | I28: =ROUND((0.75*AO28)+(AF28*(J28/144)),1) -> -7 | J28: 66 | K28: 287 | L28: 245 | M28: 49 | N28: 83 | O28: 14 | P28: 3 | Q28: 8 | R28: 57 | S28: 4 | T28: 1 | U28: 35 | V28: 3 | W28: 2 | X28: 41 | Y28: 2 | Z28: 4 | AA28: =ROUND(N28/L28,3) -> 0.339 | AB28: =ROUND((N28+U28+V28)/(L28+U28+V28+Z28),3) -> 0.422 | AC28: =ROUND(((N28-O28-P28-Q28)+2*O28+3*P28+4*Q28)/L28,3) -> 0.518 | AD28: =ROUND(AB28+AC28,3) -> 0.94 | AE28: =ROUND((('연도별 상수'!$N$46*(U28-W28))+('연도별 상수'!$O$46*V28)+('연도별 상수'!$P$46*(N28-O28-P28-Q28))+('연도별 상수'!$Q$46*O28)+('연도별 상수'!$R$46*P28)+('연도별 상수'!$S$46*Q28))/(L28+U28+V28-W28+Z28),3) -> 0.421 | AF28: ='연도별 상수'!AG$7 -> -5.5 | AG28: ='연도별 상수'!AH$7 -> -5 | AH28: ='연도별 상수'!$H$46 -> 1.055356 | AI28: 0 | AJ28: 0 | AK28: 0 | AL28: 0 | AM28: 0 | AN28: 0 | AO28: -6 | AP28: =K28 -> 287 | AQ28: 0
A29: 28 | B29: 박승규 | C29: ='연도별 상수'!AE$9 -> RF | D29: SAM | E29: ='연도별 상수'!$A$46 -> 2026 | F29: =ROUND(((H29)+(I29)+(AG29*K29/600)+(20*K29/600))/'연도별 상수'!$U$46,2) -> 1.58 | G29: =ROUND(100*(((((AE29-'리그 타자'!$B$46)/'연도별 상수'!$T$46)+'연도별 상수'!$W$46))+('연도별 상수'!$W$46*(1-AH29)))/'연도별 상수'!$W$46,1) -> 131.6 | H29: =ROUND((((AE29-'리그 타자'!$B$46)/'연도별 상수'!$T$46)*K29/AH29)+(S29*'연도별 상수'!$AB$46-T29*'연도별 상수'!$AC$46)-((S29+T29)*('연도별 상수'!$AD$46*0.2-(1-'연도별 상수'!$AD$46)*0.4))+0.05*(S29+O29+P29),1) -> 13.5 | I29: =ROUND((0.75*AO29)+(AF29*(J29/144)),1) -> -3 | J29: 69 | K29: 262 | L29: 217 | M29: 46 | N29: 62 | O29: 10 | P29: 5 | Q29: 9 | R29: 34 | S29: 6 | T29: 1 | U29: 40 | V29: 3 | W29: 1 | X29: 37 | Y29: 5 | Z29: 2 | AA29: =ROUND(N29/L29,3) -> 0.286 | AB29: =ROUND((N29+U29+V29)/(L29+U29+V29+Z29),3) -> 0.401 | AC29: =ROUND(((N29-O29-P29-Q29)+2*O29+3*P29+4*Q29)/L29,3) -> 0.502 | AD29: =ROUND(AB29+AC29,3) -> 0.903 | AE29: =ROUND((('연도별 상수'!$N$46*(U29-W29))+('연도별 상수'!$O$46*V29)+('연도별 상수'!$P$46*(N29-O29-P29-Q29))+('연도별 상수'!$Q$46*O29)+('연도별 상수'!$R$46*P29)+('연도별 상수'!$S$46*Q29))/(L29+U29+V29-W29+Z29),3) -> 0.406 | AF29: ='연도별 상수'!AG$9 -> -4.77 | AG29: ='연도별 상수'!AH$9 -> -5 | AH29: ='연도별 상수'!$H$46 -> 1.055356 | AI29: 0 | AJ29: 0 | AK29: 0 | AL29: 0 | AM29: 0 | AN29: 0 | AO29: -1 | AP29: =K29 -> 262 | AQ29: 0
A30: 29 | B30: 디아즈 | C30: ='연도별 상수'!AE$3 -> 1B | D30: SAM | E30: ='연도별 상수'!$A$46 -> 2026 | F30: =ROUND(((H30)+(I30)+(AG30*K30/600)+(20*K30/600))/'연도별 상수'!$U$46,2) -> 1.47 | G30: =ROUND(100*(((((AE30-'리그 타자'!$B$46)/'연도별 상수'!$T$46)+'연도별 상수'!$W$46))+('연도별 상수'!$W$46*(1-AH30)))/'연도별 상수'!$W$46,1) -> 123.5 | H30: =ROUND((((AE30-'리그 타자'!$B$46)/'연도별 상수'!$T$46)*K30/AH30)+(S30*'연도별 상수'!$AB$46-T30*'연도별 상수'!$AC$46)-((S30+T30)*('연도별 상수'!$AD$46*0.2-(1-'연도별 상수'!$AD$46)*0.4))+0.05*(S30+O30+P30),1) -> 15 | I30: =ROUND((0.75*AO30)+(AF30*(J30/144)),1) -> -6.8 | J30: 85 | K30: 382 | L30: 332 | M30: 52 | N30: 98 | O30: 20 | P30: 0 | Q30: 16 | R30: 71 | S30: 2 | T30: 0 | U30: 46 | V30: 1 | W30: 3 | X30: 60 | Y30: 9 | Z30: 3 | AA30: =ROUND(N30/L30,3) -> 0.295 | AB30: =ROUND((N30+U30+V30)/(L30+U30+V30+Z30),3) -> 0.38 | AC30: =ROUND(((N30-O30-P30-Q30)+2*O30+3*P30+4*Q30)/L30,3) -> 0.5 | AD30: =ROUND(AB30+AC30,3) -> 0.88 | AE30: =ROUND((('연도별 상수'!$N$46*(U30-W30))+('연도별 상수'!$O$46*V30)+('연도별 상수'!$P$46*(N30-O30-P30-Q30))+('연도별 상수'!$Q$46*O30)+('연도별 상수'!$R$46*P30)+('연도별 상수'!$S$46*Q30))/(L30+U30+V30-W30+Z30),3) -> 0.393 | AF30: ='연도별 상수'!AG$3 -> -10.22 | AG30: ='연도별 상수'!AH$3 -> -8 | AH30: ='연도별 상수'!$H$46 -> 1.055356 | AI30: 0 | AJ30: 0 | AK30: 0 | AL30: 0 | AM30: 0 | AN30: 0 | AO30: -1 | AP30: =K30 -> 382 | AQ30: 1
A31: 30 | B31: 카메론 | C31: ='연도별 상수'!AE$9 -> RF | D31: DOO | E31: ='연도별 상수'!$A$46 -> 2026 | F31: =ROUND(((H31)+(I31)+(AG31*K31/600)+(20*K31/600))/'연도별 상수'!$U$46,2) -> 1.5 | G31: =ROUND(100*(((((AE31-'리그 타자'!$B$46)/'연도별 상수'!$T$46)+'연도별 상수'!$W$46))+('연도별 상수'!$W$46*(1-AH31)))/'연도별 상수'!$W$46,1) -> 131.3 | H31: =ROUND((((AE31-'리그 타자'!$B$46)/'연도별 상수'!$T$46)*K31/AH31)+(S31*'연도별 상수'!$AB$46-T31*'연도별 상수'!$AC$46)-((S31+T31)*('연도별 상수'!$AD$46*0.2-(1-'연도별 상수'!$AD$46)*0.4))+0.05*(S31+O31+P31),1) -> 11.5 | I31: =ROUND((0.75*AO31)+(AF31*(J31/144)),1) -> -3.2 | J31: 75 | K31: 314 | L31: 279 | M31: 39 | N31: 80 | O31: 19 | P31: 3 | Q31: 9 | R31: 43 | S31: 9 | T31: 0 | U31: 30 | V31: 3 | W31: 0 | X31: 53 | Y31: 9 | Z31: 2 | AA31: =ROUND(N31/L31,3) -> 0.287 | AB31: =ROUND((N31+U31+V31)/(L31+U31+V31+Z31),3) -> 0.36 | AC31: =ROUND(((N31-O31-P31-Q31)+2*O31+3*P31+4*Q31)/L31,3) -> 0.473 | AD31: =ROUND(AB31+AC31,3) -> 0.833 | AE31: =ROUND((('연도별 상수'!$N$46*(U31-W31))+('연도별 상수'!$O$46*V31)+('연도별 상수'!$P$46*(N31-O31-P31-Q31))+('연도별 상수'!$Q$46*O31)+('연도별 상수'!$R$46*P31)+('연도별 상수'!$S$46*Q31))/(L31+U31+V31-W31+Z31),3) -> 0.376 | AF31: ='연도별 상수'!AG$9 -> -4.77 | AG31: ='연도별 상수'!AH$9 -> -5 | AH31: ='연도별 상수'!$B$46 -> 0.871842 | AI31: 0 | AJ31: 0 | AK31: 0 | AL31: 0 | AM31: 0 | AN31: 0 | AO31: -1 | AP31: =K31 -> 314 | AQ31: 1
A32: 31 | B32: 김상수 | C32: ='연도별 상수'!AE$4 -> 2B | D32: KT | E32: ='연도별 상수'!$A$46 -> 2026 | F32: =ROUND(((H32)+(I32)+(AG32*K32/600)+(20*K32/600))/'연도별 상수'!$U$46,2) -> 1.44 | G32: =ROUND(100*(((((AE32-'리그 타자'!$B$46)/'연도별 상수'!$T$46)+'연도별 상수'!$W$46))+('연도별 상수'!$W$46*(1-AH32)))/'연도별 상수'!$W$46,1) -> 91.5 | H32: =ROUND((((AE32-'리그 타자'!$B$46)/'연도별 상수'!$T$46)*K32/AH32)+(S32*'연도별 상수'!$AB$46-T32*'연도별 상수'!$AC$46)-((S32+T32)*('연도별 상수'!$AD$46*0.2-(1-'연도별 상수'!$AD$46)*0.4))+0.05*(S32+O32+P32),1) -> -1.5 | I32: =ROUND((0.75*AO32)+(AF32*(J32/144)),1) -> 5.9 | J32: 75 | K32: 291 | L32: 242 | M32: 24 | N32: 69 | O32: 7 | P32: 1 | Q32: 0 | R32: 24 | S32: 0 | T32: 3 | U32: 36 | V32: 5 | W32: 0 | X32: 34 | Y32: 8 | Z32: 1 | AA32: =ROUND(N32/L32,3) -> 0.285 | AB32: =ROUND((N32+U32+V32)/(L32+U32+V32+Z32),3) -> 0.387 | AC32: =ROUND(((N32-O32-P32-Q32)+2*O32+3*P32+4*Q32)/L32,3) -> 0.322 | AD32: =ROUND(AB32+AC32,3) -> 0.709 | AE32: =ROUND((('연도별 상수'!$N$46*(U32-W32))+('연도별 상수'!$O$46*V32)+('연도별 상수'!$P$46*(N32-O32-P32-Q32))+('연도별 상수'!$Q$46*O32)+('연도별 상수'!$R$46*P32)+('연도별 상수'!$S$46*Q32))/(L32+U32+V32-W32+Z32),3) -> 0.344 | AF32: ='연도별 상수'!AG$4 -> 1.22 | AG32: ='연도별 상수'!AH$4 -> 3 | AH32: ='연도별 상수'!$E$46 -> 1.069855 | AI32: 0 | AJ32: 0 | AK32: 0 | AL32: 0 | AM32: 0 | AN32: 0 | AO32: 7 | AP32: =K32 -> 291 | AQ32: 0
A33: 32 | B33: 전민재 | C33: ='연도별 상수'!AE$6 -> SS | D33: LOT | E33: ='연도별 상수'!$A$46 -> 2026 | F33: =ROUND(((H33)+(I33)+(AG33*K33/600)+(20*K33/600))/'연도별 상수'!$U$46,2) -> 1.43 | G33: =ROUND(100*(((((AE33-'리그 타자'!$B$46)/'연도별 상수'!$T$46)+'연도별 상수'!$W$46))+('연도별 상수'!$W$46*(1-AH33)))/'연도별 상수'!$W$46,1) -> 72.8 | H33: =ROUND((((AE33-'리그 타자'!$B$46)/'연도별 상수'!$T$46)*K33/AH33)+(S33*'연도별 상수'!$AB$46-T33*'연도별 상수'!$AC$46)-((S33+T33)*('연도별 상수'!$AD$46*0.2-(1-'연도별 상수'!$AD$46)*0.4))+0.05*(S33+O33+P33),1) -> -2.5 | I33: =ROUND((0.75*AO33)+(AF33*(J33/144)),1) -> 4.6 | J33: 82 | K33: 297 | L33: 272 | M33: 29 | N33: 74 | O33: 12 | P33: 0 | Q33: 8 | R33: 43 | S33: 9 | T33: 3 | U33: 17 | V33: 3 | W33: 0 | X33: 61 | Y33: 5 | Z33: 3 | AA33: =ROUND(N33/L33,3) -> 0.272 | AB33: =ROUND((N33+U33+V33)/(L33+U33+V33+Z33),3) -> 0.319 | AC33: =ROUND(((N33-O33-P33-Q33)+2*O33+3*P33+4*Q33)/L33,3) -> 0.404 | AD33: =ROUND(AB33+AC33,3) -> 0.723 | AE33: =ROUND((('연도별 상수'!$N$46*(U33-W33))+('연도별 상수'!$O$46*V33)+('연도별 상수'!$P$46*(N33-O33-P33-Q33))+('연도별 상수'!$Q$46*O33)+('연도별 상수'!$R$46*P33)+('연도별 상수'!$S$46*Q33))/(L33+U33+V33-W33+Z33),3) -> 0.329 | AF33: ='연도별 상수'!AG$6 -> 2.77 | AG33: ='연도별 상수'!AH$6 -> 7 | AH33: ='연도별 상수'!$I$46 -> 1.163773 | AI33: 0 | AJ33: 0 | AK33: 0 | AL33: 0 | AM33: 0 | AN33: 0 | AO33: 4 | AP33: =K33 -> 297 | AQ33: 0
A34: 33 | B34: 최형우 | C34: ='연도별 상수'!AE$10 -> DH | D34: SAM | E34: ='연도별 상수'!$A$46 -> 2026 | F34: =ROUND(((H34)+(I34)+(AG34*K34/600)+(20*K34/600))/'연도별 상수'!$U$46,2) -> 1.43 | G34: =ROUND(100*(((((AE34-'리그 타자'!$B$46)/'연도별 상수'!$T$46)+'연도별 상수'!$W$46))+('연도별 상수'!$W$46*(1-AH34)))/'연도별 상수'!$W$46,1) -> 139.7 | H34: =ROUND((((AE34-'리그 타자'!$B$46)/'연도별 상수'!$T$46)*K34/AH34)+(S34*'연도별 상수'!$AB$46-T34*'연도별 상수'!$AC$46)-((S34+T34)*('연도별 상수'!$AD$46*0.2-(1-'연도별 상수'!$AD$46)*0.4))+0.05*(S34+O34+P34),1) -> 20.3 | I34: =ROUND((0.75*AO34)+(AF34*(J34/144)),1) -> -7.8 | J34: 81 | K34: 348 | L34: 289 | M34: 40 | N34: 95 | O34: 16 | P34: 0 | Q34: 12 | R34: 66 | S34: 1 | T34: 0 | U34: 50 | V34: 3 | W34: 4 | X34: 48 | Y34: 11 | Z34: 6 | AA34: =ROUND(N34/L34,3) -> 0.329 | AB34: =ROUND((N34+U34+V34)/(L34+U34+V34+Z34),3) -> 0.425 | AC34: =ROUND(((N34-O34-P34-Q34)+2*O34+3*P34+4*Q34)/L34,3) -> 0.509 | AD34: =ROUND(AB34+AC34,3) -> 0.934 | AE34: =ROUND((('연도별 상수'!$N$46*(U34-W34))+('연도별 상수'!$O$46*V34)+('연도별 상수'!$P$46*(N34-O34-P34-Q34))+('연도별 상수'!$Q$46*O34)+('연도별 상수'!$R$46*P34)+('연도별 상수'!$S$46*Q34))/(L34+U34+V34-W34+Z34),3) -> 0.419 | AF34: ='연도별 상수'!AG$10 -> -12.5 | AG34: ='연도별 상수'!AH$10 -> -15 | AH34: ='연도별 상수'!$H$46 -> 1.055356 | AI34: 0 | AJ34: 0 | AK34: 0 | AL34: 0 | AM34: 0 | AN34: 0 | AO34: -1 | AP34: =K34 -> 348 | AQ34: 0
A35: 34 | B35: 정준재 | C35: ='연도별 상수'!AE$4 -> 2B | D35: SSG | E35: ='연도별 상수'!$A$46 -> 2026 | F35: =ROUND(((H35)+(I35)+(AG35*K35/600)+(20*K35/600))/'연도별 상수'!$U$46,2) -> 1.27 | G35: =ROUND(100*(((((AE35-'리그 타자'!$B$46)/'연도별 상수'!$T$46)+'연도별 상수'!$W$46))+('연도별 상수'!$W$46*(1-AH35)))/'연도별 상수'!$W$46,1) -> 94.9 | H35: =ROUND((((AE35-'리그 타자'!$B$46)/'연도별 상수'!$T$46)*K35/AH35)+(S35*'연도별 상수'!$AB$46-T35*'연도별 상수'!$AC$46)-((S35+T35)*('연도별 상수'!$AD$46*0.2-(1-'연도별 상수'!$AD$46)*0.4))+0.05*(S35+O35+P35),1) -> -3.7 | I35: =ROUND((0.75*AO35)+(AF35*(J35/144)),1) -> 4.5 | J35: 83 | K35: 336 | L35: 285 | M35: 43 | N35: 79 | O35: 8 | P35: 6 | Q35: 1 | R35: 27 | S35: 12 | T35: 4 | U35: 29 | V35: 5 | W35: 0 | X35: 46 | Y35: 4 | Z35: 5 | AA35: =ROUND(N35/L35,3) -> 0.277 | AB35: =ROUND((N35+U35+V35)/(L35+U35+V35+Z35),3) -> 0.349 | AC35: =ROUND(((N35-O35-P35-Q35)+2*O35+3*P35+4*Q35)/L35,3) -> 0.358 | AD35: =ROUND(AB35+AC35,3) -> 0.707 | AE35: =ROUND((('연도별 상수'!$N$46*(U35-W35))+('연도별 상수'!$O$46*V35)+('연도별 상수'!$P$46*(N35-O35-P35-Q35))+('연도별 상수'!$Q$46*O35)+('연도별 상수'!$R$46*P35)+('연도별 상수'!$S$46*Q35))/(L35+U35+V35-W35+Z35),3) -> 0.329 | AF35: ='연도별 상수'!AG$4 -> 1.22 | AG35: ='연도별 상수'!AH$4 -> 3 | AH35: ='연도별 상수'!$D$46 -> 0.943387 | AI35: 0 | AJ35: 0 | AK35: 0 | AL35: 0 | AM35: 0 | AN35: 0 | AO35: 5 | AP35: =K35 -> 336 | AQ35: 0
A36: 35 | B36: 황성빈 | C36: ='연도별 상수'!AE$8 -> CF | D36: LOT | E36: ='연도별 상수'!$A$46 -> 2026 | F36: =ROUND(((H36)+(I36)+(AG36*K36/600)+(20*K36/600))/'연도별 상수'!$U$46,2) -> 1.31 | G36: =ROUND(100*(((((AE36-'리그 타자'!$B$46)/'연도별 상수'!$T$46)+'연도별 상수'!$W$46))+('연도별 상수'!$W$46*(1-AH36)))/'연도별 상수'!$W$46,1) -> 69.1 | H36: =ROUND((((AE36-'리그 타자'!$B$46)/'연도별 상수'!$T$46)*K36/AH36)+(S36*'연도별 상수'!$AB$46-T36*'연도별 상수'!$AC$46)-((S36+T36)*('연도별 상수'!$AD$46*0.2-(1-'연도별 상수'!$AD$46)*0.4))+0.05*(S36+O36+P36),1) -> 0.1 | I36: =ROUND((0.75*AO36)+(AF36*(J36/144)),1) -> 4 | J36: 66 | K36: 263 | L36: 239 | M36: 38 | N36: 69 | O36: 6 | P36: 6 | Q36: 0 | R36: 20 | S36: 32 | T36: 6 | U36: 17 | V36: 1 | W36: 0 | X36: 42 | Y36: 1 | Z36: 2 | AA36: =ROUND(N36/L36,3) -> 0.289 | AB36: =ROUND((N36+U36+V36)/(L36+U36+V36+Z36),3) -> 0.336 | AC36: =ROUND(((N36-O36-P36-Q36)+2*O36+3*P36+4*Q36)/L36,3) -> 0.364 | AD36: =ROUND(AB36+AC36,3) -> 0.7 | AE36: =ROUND((('연도별 상수'!$N$46*(U36-W36))+('연도별 상수'!$O$46*V36)+('연도별 상수'!$P$46*(N36-O36-P36-Q36))+('연도별 상수'!$Q$46*O36)+('연도별 상수'!$R$46*P36)+('연도별 상수'!$S$46*Q36))/(L36+U36+V36-W36+Z36),3) -> 0.323 | AF36: ='연도별 상수'!AG$8 -> 2.22 | AG36: ='연도별 상수'!AH$8 -> 3 | AH36: ='연도별 상수'!$I$46 -> 1.163773 | AI36: 0 | AJ36: 0 | AK36: 0 | AL36: 0 | AM36: 0 | AN36: 0 | AO36: 4 | AP36: =K36 -> 263 | AQ36: 0
A37: 36 | B37: 심우준 | C37: ='연도별 상수'!AE$6 -> SS | D37: HAN | E37: ='연도별 상수'!$A$46 -> 2026 | F37: =ROUND(((H37)+(I37)+(AG37*K37/600)+(20*K37/600))/'연도별 상수'!$U$46,2) -> 1.3 | G37: =ROUND(100*(((((AE37-'리그 타자'!$B$46)/'연도별 상수'!$T$46)+'연도별 상수'!$W$46))+('연도별 상수'!$W$46*(1-AH37)))/'연도별 상수'!$W$46,1) -> 70.9 | H37: =ROUND((((AE37-'리그 타자'!$B$46)/'연도별 상수'!$T$46)*K37/AH37)+(S37*'연도별 상수'!$AB$46-T37*'연도별 상수'!$AC$46)-((S37+T37)*('연도별 상수'!$AD$46*0.2-(1-'연도별 상수'!$AD$46)*0.4))+0.05*(S37+O37+P37),1) -> -0.6 | I37: =ROUND((0.75*AO37)+(AF37*(J37/144)),1) -> 2.9 | J37: 74 | K37: 261 | L37: 225 | M37: 39 | N37: 60 | O37: 7 | P37: 0 | Q37: 3 | R37: 24 | S37: 15 | T37: 1 | U37: 27 | V37: 3 | W37: 0 | X37: 45 | Y37: 1 | Z37: 1 | AA37: =ROUND(N37/L37,3) -> 0.267 | AB37: =ROUND((N37+U37+V37)/(L37+U37+V37+Z37),3) -> 0.352 | AC37: =ROUND(((N37-O37-P37-Q37)+2*O37+3*P37+4*Q37)/L37,3) -> 0.338 | AD37: =ROUND(AB37+AC37,3) -> 0.69 | AE37: =ROUND((('연도별 상수'!$N$46*(U37-W37))+('연도별 상수'!$O$46*V37)+('연도별 상수'!$P$46*(N37-O37-P37-Q37))+('연도별 상수'!$Q$46*O37)+('연도별 상수'!$R$46*P37)+('연도별 상수'!$S$46*Q37))/(L37+U37+V37-W37+Z37),3) -> 0.327 | AF37: ='연도별 상수'!AG$6 -> 2.77 | AG37: ='연도별 상수'!AH$6 -> 7 | AH37: ='연도별 상수'!$F$46 -> 1.170772 | AI37: 0 | AJ37: 0 | AK37: 0 | AL37: 0 | AM37: 0 | AN37: 0 | AO37: 2 | AP37: =K37 -> 261 | AQ37: 0
A38: 37 | B38: 박건우 | C38: ='연도별 상수'!AE$9 -> RF | D38: NC | E38: ='연도별 상수'!$A$46 -> 2026 | F38: =ROUND(((H38)+(I38)+(AG38*K38/600)+(20*K38/600))/'연도별 상수'!$U$46,2) -> 1.26 | G38: =ROUND(100*(((((AE38-'리그 타자'!$B$46)/'연도별 상수'!$T$46)+'연도별 상수'!$W$46))+('연도별 상수'!$W$46*(1-AH38)))/'연도별 상수'!$W$46,1) -> 124.7 | H38: =ROUND((((AE38-'리그 타자'!$B$46)/'연도별 상수'!$T$46)*K38/AH38)+(S38*'연도별 상수'!$AB$46-T38*'연도별 상수'!$AC$46)-((S38+T38)*('연도별 상수'!$AD$46*0.2-(1-'연도별 상수'!$AD$46)*0.4))+0.05*(S38+O38+P38),1) -> 9.8 | I38: =ROUND((0.75*AO38)+(AF38*(J38/144)),1) -> -4.1 | J38: 79 | K38: 318 | L38: 268 | M38: 41 | N38: 77 | O38: 11 | P38: 0 | Q38: 15 | R38: 50 | S38: 5 | T38: 2 | U38: 40 | V38: 1 | W38: 5 | X38: 58 | Y38: 5 | Z38: 9 | AA38: =ROUND(N38/L38,3) -> 0.287 | AB38: =ROUND((N38+U38+V38)/(L38+U38+V38+Z38),3) -> 0.371 | AC38: =ROUND(((N38-O38-P38-Q38)+2*O38+3*P38+4*Q38)/L38,3) -> 0.496 | AD38: =ROUND(AB38+AC38,3) -> 0.867 | AE38: =ROUND((('연도별 상수'!$N$46*(U38-W38))+('연도별 상수'!$O$46*V38)+('연도별 상수'!$P$46*(N38-O38-P38-Q38))+('연도별 상수'!$Q$46*O38)+('연도별 상수'!$R$46*P38)+('연도별 상수'!$S$46*Q38))/(L38+U38+V38-W38+Z38),3) -> 0.381 | AF38: ='연도별 상수'!AG$9 -> -4.77 | AG38: ='연도별 상수'!AH$9 -> -5 | AH38: ='연도별 상수'!$J$46 -> 0.968492 | AI38: 0 | AJ38: 0 | AK38: 0 | AL38: 0 | AM38: 0 | AN38: 0 | AO38: -2 | AP38: =K38 -> 318 | AQ38: 0
A39: 38 | B39: 김건희 | C39: ='연도별 상수'!AE$2 -> C | D39: KIW | E39: ='연도별 상수'!$A$46 -> 2026 | F39: =ROUND(((H39)+(I39)+(AG39*K39/600)+(20*K39/600))/'연도별 상수'!$U$46,2) -> 1.22 | G39: =ROUND(100*(((((AE39-'리그 타자'!$B$46)/'연도별 상수'!$T$46)+'연도별 상수'!$W$46))+('연도별 상수'!$W$46*(1-AH39)))/'연도별 상수'!$W$46,1) -> 94.8 | H39: =ROUND((((AE39-'리그 타자'!$B$46)/'연도별 상수'!$T$46)*K39/AH39)+(S39*'연도별 상수'!$AB$46-T39*'연도별 상수'!$AC$46)-((S39+T39)*('연도별 상수'!$AD$46*0.2-(1-'연도별 상수'!$AD$46)*0.4))+0.05*(S39+O39+P39),1) -> -3.9 | I39: =ROUND((0.75*AO39)+(AF39*(J39/144)),1) -> 3.7 | J39: 80 | K39: 267 | L39: 236 | M39: 18 | N39: 61 | O39: 12 | P39: 0 | Q39: 6 | R39: 34 | S39: 0 | T39: 0 | U39: 25 | V39: 1 | W39: 1 | X39: 74 | Y39: 3 | Z39: 3 | AA39: =ROUND(N39/L39,3) -> 0.258 | AB39: =ROUND((N39+U39+V39)/(L39+U39+V39+Z39),3) -> 0.328 | AC39: =ROUND(((N39-O39-P39-Q39)+2*O39+3*P39+4*Q39)/L39,3) -> 0.386 | AD39: =ROUND(AB39+AC39,3) -> 0.714 | AE39: =ROUND((('연도별 상수'!$N$46*(U39-W39))+('연도별 상수'!$O$46*V39)+('연도별 상수'!$P$46*(N39-O39-P39-Q39))+('연도별 상수'!$Q$46*O39)+('연도별 상수'!$R$46*P39)+('연도별 상수'!$S$46*Q39))/(L39+U39+V39-W39+Z39),3) -> 0.327 | AF39: ='연도별 상수'!AG$2 -> 5.22 | AG39: ='연도별 상수'!AH$2 -> 10 | AH39: ='연도별 상수'!$C$46 -> 0.931727 | AI39: 0 | AJ39: 0 | AK39: 0 | AL39: 0 | AM39: 0 | AN39: 0 | AO39: 1 | AP39: =K39 -> 267 | AQ39: 0
A40: 39 | B40: 오지환 | C40: ='연도별 상수'!AE$6 -> SS | D40: LG | E40: ='연도별 상수'!$A$46 -> 2026 | F40: =ROUND(((H40)+(I40)+(AG40*K40/600)+(20*K40/600))/'연도별 상수'!$U$46,2) -> 1.09 | G40: =ROUND(100*(((((AE40-'리그 타자'!$B$46)/'연도별 상수'!$T$46)+'연도별 상수'!$W$46))+('연도별 상수'!$W$46*(1-AH40)))/'연도별 상수'!$W$46,1) -> 100.1 | H40: =ROUND((((AE40-'리그 타자'!$B$46)/'연도별 상수'!$T$46)*K40/AH40)+(S40*'연도별 상수'!$AB$46-T40*'연도별 상수'!$AC$46)-((S40+T40)*('연도별 상수'!$AD$46*0.2-(1-'연도별 상수'!$AD$46)*0.4))+0.05*(S40+O40+P40),1) -> -5 | I40: =ROUND((0.75*AO40)+(AF40*(J40/144)),1) -> 4.5 | J40: 78 | K40: 273 | L40: 234 | M40: 31 | N40: 59 | O40: 9 | P40: 0 | Q40: 6 | R40: 40 | S40: 3 | T40: 2 | U40: 27 | V40: 3 | W40: 0 | X40: 54 | Y40: 4 | Z40: 3 | AA40: =ROUND(N40/L40,3) -> 0.252 | AB40: =ROUND((N40+U40+V40)/(L40+U40+V40+Z40),3) -> 0.333 | AC40: =ROUND(((N40-O40-P40-Q40)+2*O40+3*P40+4*Q40)/L40,3) -> 0.368 | AD40: =ROUND(AB40+AC40,3) -> 0.701 | AE40: =ROUND((('연도별 상수'!$N$46*(U40-W40))+('연도별 상수'!$O$46*V40)+('연도별 상수'!$P$46*(N40-O40-P40-Q40))+('연도별 상수'!$Q$46*O40)+('연도별 상수'!$R$46*P40)+('연도별 상수'!$S$46*Q40))/(L40+U40+V40-W40+Z40),3) -> 0.326 | AF40: ='연도별 상수'!AG$6 -> 2.77 | AG40: ='연도별 상수'!AH$6 -> 7 | AH40: ='연도별 상수'!$B$46 -> 0.871842 | AI40: 0 | AJ40: 0 | AK40: 0 | AL40: 0 | AM40: 0 | AN40: 0 | AO40: 4 | AP40: =K40 -> 273 | AQ40: 0
...

Sheet 확장-타자
A1: RK | B1: Player | C1: Pos | D1: Team | E1: Year | F1: oWAR | G1: PA | H1: XBH | I1: wOBA | J1: wRC | K1: wRC+ | L1: OPS+ | M1: K% | N1: BB% | O1: BB/K | P1: HR% | Q1: BABIP | R1: IsoD | S1: IsoP | T1: WPA | U1: RE24 | V1: RC27 | W1: REW | X1: whiff% | Y1: chase%
A2: ='기본-타자'!A2 -> 1 | B2: ='기본-타자'!B2 -> 오스틴 | C2: ='기본-타자'!C2 -> 1B | D2: ='기본-타자'!D2 -> LG | E2: ='기본-타자'!E2 -> 2026 | F2: =ROUND((('기본-타자'!H2)+('기본-타자'!AG2*'기본-타자'!K2/600)+(20*'기본-타자'!K2/600))/'연도별 상수'!$U$46,2) -> 4.76 | G2: ='기본-타자'!K2 -> 378 | H2: ='기본-타자'!O2+'기본-타자'!P2+'기본-타자'!Q2 -> 48 | I2: =ROUND('기본-타자'!AE2,3) -> 0.469 | J2: =ROUND(((I2-'리그 타자'!$B$46)/'연도별 상수'!$T$46+'연도별 상수'!$W$46)*G2,1) -> 86.4 | K2: ='기본-타자'!G2 -> 189.2 | L2: =ROUND(100*('기본-타자'!AB2/'리그 타자'!$R$46+'기본-타자'!AC2/'리그 타자'!$S$46-1)/'기본-타자'!AH2,1) -> 210.9 | M2: =ROUND('기본-타자'!X2/G2*100,1) -> 15.3 | N2: =ROUND('기본-타자'!U2/G2*100,1) -> 11.1 | O2: =ROUND('기본-타자'!U2/'기본-타자'!X2,1) -> 0.7 | P2: =ROUND('기본-타자'!Q2/G2*100,1) -> 7.1 | Q2: =ROUND(('기본-타자'!N2-'기본-타자'!Q2)/('기본-타자'!L2-'기본-타자'!X2-'기본-타자'!Q2+'기본-타자'!Z2),3) -> 0.343 | R2: =ROUND('기본-타자'!AB2-'기본-타자'!AA2,3) -> 0.082 | S2: =ROUND('기본-타자'!AC2-'기본-타자'!AA2,3) -> 0.322 | T2: ='기본-타자'!AK2 -> 0 | U2: ='기본-타자'!AL2 -> 0 | V2: ='기본-타자'!AN2 -> 0 | W2: ='기본-타자'!AM2 -> 0 | X2: ='기본-타자'!AI2 -> 0 | Y2: ='기본-타자'!AJ2 -> 0
A3: ='기본-타자'!A3 -> 2 | B3: ='기본-타자'!B3 -> 김주원 | C3: ='기본-타자'!C3 -> SS | D3: ='기본-타자'!D3 -> NC | E3: ='기본-타자'!E3 -> 2026 | F3: =ROUND((('기본-타자'!H3)+('기본-타자'!AG3*'기본-타자'!K3/600)+(20*'기본-타자'!K3/600))/'연도별 상수'!$U$46,2) -> 3.01 | G3: ='기본-타자'!K3 -> 366 | H3: ='기본-타자'!O3+'기본-타자'!P3+'기본-타자'!Q3 -> 28 | I3: =ROUND('기본-타자'!AE3,3) -> 0.389 | J3: =ROUND(((I3-'리그 타자'!$B$46)/'연도별 상수'!$T$46+'연도별 상수'!$W$46)*G3,1) -> 60 | K3: ='기본-타자'!G3 -> 129.7 | L3: =ROUND(100*('기본-타자'!AB3/'리그 타자'!$R$46+'기본-타자'!AC3/'리그 타자'!$S$46-1)/'기본-타자'!AH3,1) -> 131.5 | M3: =ROUND('기본-타자'!X3/G3*100,1) -> 13.4 | N3: =ROUND('기본-타자'!U3/G3*100,1) -> 7.9 | O3: =ROUND('기본-타자'!U3/'기본-타자'!X3,1) -> 0.6 | P3: =ROUND('기본-타자'!Q3/G3*100,1) -> 3.6 | Q3: =ROUND(('기본-타자'!N3-'기본-타자'!Q3)/('기본-타자'!L3-'기본-타자'!X3-'기본-타자'!Q3+'기본-타자'!Z3),3) -> 0.326 | R3: =ROUND('기본-타자'!AB3-'기본-타자'!AA3,3) -> 0.078 | S3: =ROUND('기본-타자'!AC3-'기본-타자'!AA3,3) -> 0.169 | T3: ='기본-타자'!AK3 -> 0 | U3: ='기본-타자'!AL3 -> 0 | V3: ='기본-타자'!AN3 -> 0 | W3: ='기본-타자'!AM3 -> 0 | X3: ='기본-타자'!AI3 -> 0 | Y3: ='기본-타자'!AJ3 -> 0
A4: ='기본-타자'!A4 -> 3 | B4: ='기본-타자'!B4 -> 김도영 | C4: ='기본-타자'!C4 -> 3B | D4: ='기본-타자'!D4 -> KIA | E4: ='기본-타자'!E4 -> 2026 | F4: =ROUND((('기본-타자'!H4)+('기본-타자'!AG4*'기본-타자'!K4/600)+(20*'기본-타자'!K4/600))/'연도별 상수'!$U$46,2) -> 3.97 | G4: ='기본-타자'!K4 -> 371 | H4: ='기본-타자'!O4+'기본-타자'!P4+'기본-타자'!Q4 -> 45 | I4: =ROUND('기본-타자'!AE4,3) -> 0.436 | J4: =ROUND(((I4-'리그 타자'!$B$46)/'연도별 상수'!$T$46+'연도별 상수'!$W$46)*G4,1) -> 74.9 | K4: ='기본-타자'!G4 -> 163.9 | L4: =ROUND(100*('기본-타자'!AB4/'리그 타자'!$R$46+'기본-타자'!AC4/'리그 타자'!$S$46-1)/'기본-타자'!AH4,1) -> 179.5 | M4: =ROUND('기본-타자'!X4/G4*100,1) -> 16.4 | N4: =ROUND('기본-타자'!U4/G4*100,1) -> 12.7 | O4: =ROUND('기본-타자'!U4/'기본-타자'!X4,1) -> 0.8 | P4: =ROUND('기본-타자'!Q4/G4*100,1) -> 7.3 | Q4: =ROUND(('기본-타자'!N4-'기본-타자'!Q4)/('기본-타자'!L4-'기본-타자'!X4-'기본-타자'!Q4+'기본-타자'!Z4),3) -> 0.29 | R4: =ROUND('기본-타자'!AB4-'기본-타자'!AA4,3) -> 0.096 | S4: =ROUND('기본-타자'!AC4-'기본-타자'!AA4,3) -> 0.318 | T4: ='기본-타자'!AK4 -> 0 | U4: ='기본-타자'!AL4 -> 0 | V4: ='기본-타자'!AN4 -> 0 | W4: ='기본-타자'!AM4 -> 0 | X4: ='기본-타자'!AI4 -> 0 | Y4: ='기본-타자'!AJ4 -> 0
A5: ='기본-타자'!A5 -> 4 | B5: ='기본-타자'!B5 -> 박민우 | C5: ='기본-타자'!C5 -> 2B | D5: ='기본-타자'!D5 -> NC | E5: ='기본-타자'!E5 -> 2026 | F5: =ROUND((('기본-타자'!H5)+('기본-타자'!AG5*'기본-타자'!K5/600)+(20*'기본-타자'!K5/600))/'연도별 상수'!$U$46,2) -> 3.05 | G5: ='기본-타자'!K5 -> 329 | H5: ='기본-타자'!O5+'기본-타자'!P5+'기본-타자'!Q5 -> 23 | I5: =ROUND('기본-타자'!AE5,3) -> 0.413 | J5: =ROUND(((I5-'리그 타자'!$B$46)/'연도별 상수'!$T$46+'연도별 상수'!$W$46)*G5,1) -> 60.3 | K5: ='기본-타자'!G5 -> 144.7 | L5: =ROUND(100*('기본-타자'!AB5/'리그 타자'!$R$46+'기본-타자'!AC5/'리그 타자'!$S$46-1)/'기본-타자'!AH5,1) -> 143.5 | M5: =ROUND('기본-타자'!X5/G5*100,1) -> 11.2 | N5: =ROUND('기본-타자'!U5/G5*100,1) -> 14 | O5: =ROUND('기본-타자'!U5/'기본-타자'!X5,1) -> 1.2 | P5: =ROUND('기본-타자'!Q5/G5*100,1) -> 1.5 | Q5: =ROUND(('기본-타자'!N5-'기본-타자'!Q5)/('기본-타자'!L5-'기본-타자'!X5-'기본-타자'!Q5+'기본-타자'!Z5),3) -> 0.372 | R5: =ROUND('기본-타자'!AB5-'기본-타자'!AA5,3) -> 0.102 | S5: =ROUND('기본-타자'!AC5-'기본-타자'!AA5,3) -> 0.121 | T5: ='기본-타자'!AK5 -> 0 | U5: ='기본-타자'!AL5 -> 0 | V5: ='기본-타자'!AN5 -> 0 | W5: ='기본-타자'!AM5 -> 0 | X5: ='기본-타자'!AI5 -> 0 | Y5: ='기본-타자'!AJ5 -> 0
A6: ='기본-타자'!A6 -> 5 | B6: ='기본-타자'!B6 -> 박성한 | C6: ='기본-타자'!C6 -> SS | D6: ='기본-타자'!D6 -> SSG | E6: ='기본-타자'!E6 -> 2026 | F6: =ROUND((('기본-타자'!H6)+('기본-타자'!AG6*'기본-타자'!K6/600)+(20*'기본-타자'!K6/600))/'연도별 상수'!$U$46,2) -> 3.35 | G6: ='기본-타자'!K6 -> 374 | H6: ='기본-타자'!O6+'기본-타자'!P6+'기본-타자'!Q6 -> 24 | I6: =ROUND('기본-타자'!AE6,3) -> 0.403 | J6: =ROUND(((I6-'리그 타자'!$B$46)/'연도별 상수'!$T$46+'연도별 상수'!$W$46)*G6,1) -> 65.6 | K6: ='기본-타자'!G6 -> 140.9 | L6: =ROUND(100*('기본-타자'!AB6/'리그 타자'!$R$46+'기본-타자'!AC6/'리그 타자'!$S$46-1)/'기본-타자'!AH6,1) -> 138.7 | M6: =ROUND('기본-타자'!X6/G6*100,1) -> 12 | N6: =ROUND('기본-타자'!U6/G6*100,1) -> 15 | O6: =ROUND('기본-타자'!U6/'기본-타자'!X6,1) -> 1.2 | P6: =ROUND('기본-타자'!Q6/G6*100,1) -> 0.8 | Q6: =ROUND(('기본-타자'!N6-'기본-타자'!Q6)/('기본-타자'!L6-'기본-타자'!X6-'기본-타자'!Q6+'기본-타자'!Z6),3) -> 0.379 | R6: =ROUND('기본-타자'!AB6-'기본-타자'!AA6,3) -> 0.1 | S6: =ROUND('기본-타자'!AC6-'기본-타자'!AA6,3) -> 0.099 | T6: ='기본-타자'!AK6 -> 0 | U6: ='기본-타자'!AL6 -> 0 | V6: ='기본-타자'!AN6 -> 0 | W6: ='기본-타자'!AM6 -> 0 | X6: ='기본-타자'!AI6 -> 0 | Y6: ='기본-타자'!AJ6 -> 0
A7: ='기본-타자'!A7 -> 6 | B7: ='기본-타자'!B7 -> 한준수 | C7: ='기본-타자'!C7 -> C | D7: ='기본-타자'!D7 -> KIA | E7: ='기본-타자'!E7 -> 2026 | F7: =ROUND((('기본-타자'!H7)+('기본-타자'!AG7*'기본-타자'!K7/600)+(20*'기본-타자'!K7/600))/'연도별 상수'!$U$46,2) -> 2.76 | G7: ='기본-타자'!K7 -> 256 | H7: ='기본-타자'!O7+'기본-타자'!P7+'기본-타자'!Q7 -> 23 | I7: =ROUND('기본-타자'!AE7,3) -> 0.42 | J7: =ROUND(((I7-'리그 타자'!$B$46)/'연도별 상수'!$T$46+'연도별 상수'!$W$46)*G7,1) -> 48.4 | K7: ='기본-타자'!G7 -> 153.9 | L7: =ROUND(100*('기본-타자'!AB7/'리그 타자'!$R$46+'기본-타자'!AC7/'리그 타자'!$S$46-1)/'기본-타자'!AH7,1) -> 157.9 | M7: =ROUND('기본-타자'!X7/G7*100,1) -> 14.5 | N7: =ROUND('기본-타자'!U7/G7*100,1) -> 14.1 | O7: =ROUND('기본-타자'!U7/'기본-타자'!X7,1) -> 1 | P7: =ROUND('기본-타자'!Q7/G7*100,1) -> 2.3 | Q7: =ROUND(('기본-타자'!N7-'기본-타자'!Q7)/('기본-타자'!L7-'기본-타자'!X7-'기본-타자'!Q7+'기본-타자'!Z7),3) -> 0.365 | R7: =ROUND('기본-타자'!AB7-'기본-타자'!AA7,3) -> 0.111 | S7: =ROUND('기본-타자'!AC7-'기본-타자'!AA7,3) -> 0.168 | T7: ='기본-타자'!AK7 -> 0 | U7: ='기본-타자'!AL7 -> 0 | V7: ='기본-타자'!AN7 -> 0 | W7: ='기본-타자'!AM7 -> 0 | X7: ='기본-타자'!AI7 -> 0 | Y7: ='기본-타자'!AJ7 -> 0
A8: ='기본-타자'!A8 -> 7 | B8: ='기본-타자'!B8 -> 최정 | C8: ='기본-타자'!C8 -> 3B | D8: ='기본-타자'!D8 -> SSG | E8: ='기본-타자'!E8 -> 2026 | F8: =ROUND((('기본-타자'!H8)+('기본-타자'!AG8*'기본-타자'!K8/600)+(20*'기본-타자'!K8/600))/'연도별 상수'!$U$46,2) -> 3.08 | G8: ='기본-타자'!K8 -> 300 | H8: ='기본-타자'!O8+'기본-타자'!P8+'기본-타자'!Q8 -> 37 | I8: =ROUND('기본-타자'!AE8,3) -> 0.435 | J8: =ROUND(((I8-'리그 타자'!$B$46)/'연도별 상수'!$T$46+'연도별 상수'!$W$46)*G8,1) -> 60.4 | K8: ='기본-타자'!G8 -> 160.9 | L8: =ROUND(100*('기본-타자'!AB8/'리그 타자'!$R$46+'기본-타자'!AC8/'리그 타자'!$S$46-1)/'기본-타자'!AH8,1) -> 175.2 | M8: =ROUND('기본-타자'!X8/G8*100,1) -> 22 | N8: =ROUND('기본-타자'!U8/G8*100,1) -> 12.3 | O8: =ROUND('기본-타자'!U8/'기본-타자'!X8,1) -> 0.6 | P8: =ROUND('기본-타자'!Q8/G8*100,1) -> 6.3 | Q8: =ROUND(('기본-타자'!N8-'기본-타자'!Q8)/('기본-타자'!L8-'기본-타자'!X8-'기본-타자'!Q8+'기본-타자'!Z8),3) -> 0.337 | R8: =ROUND('기본-타자'!AB8-'기본-타자'!AA8,3) -> 0.093 | S8: =ROUND('기본-타자'!AC8-'기본-타자'!AA8,3) -> 0.303 | T8: ='기본-타자'!AK8 -> 0 | U8: ='기본-타자'!AL8 -> 0 | V8: ='기본-타자'!AN8 -> 0 | W8: ='기본-타자'!AM8 -> 0 | X8: ='기본-타자'!AI8 -> 0 | Y8: ='기본-타자'!AJ8 -> 0
A9: ='기본-타자'!A9 -> 8 | B9: ='기본-타자'!B9 -> 박찬호 | C9: ='기본-타자'!C9 -> SS | D9: ='기본-타자'!D9 -> DOO | E9: ='기본-타자'!E9 -> 2026 | F9: =ROUND((('기본-타자'!H9)+('기본-타자'!AG9*'기본-타자'!K9/600)+(20*'기본-타자'!K9/600))/'연도별 상수'!$U$46,2) -> 1.73 | G9: ='기본-타자'!K9 -> 368 | H9: ='기본-타자'!O9+'기본-타자'!P9+'기본-타자'!Q9 -> 24 | I9: =ROUND('기본-타자'!AE9,3) -> 0.343 | J9: =ROUND(((I9-'리그 타자'!$B$46)/'연도별 상수'!$T$46+'연도별 상수'!$W$46)*G9,1) -> 46.7 | K9: ='기본-타자'!G9 -> 110.7 | L9: =ROUND(100*('기본-타자'!AB9/'리그 타자'!$R$46+'기본-타자'!AC9/'리그 타자'!$S$46-1)/'기본-타자'!AH9,1) -> 112 | M9: =ROUND('기본-타자'!X9/G9*100,1) -> 13.6 | N9: =ROUND('기본-타자'!U9/G9*100,1) -> 9.8 | O9: =ROUND('기본-타자'!U9/'기본-타자'!X9,1) -> 0.7 | P9: =ROUND('기본-타자'!Q9/G9*100,1) -> 1.1 | Q9: =ROUND(('기본-타자'!N9-'기본-타자'!Q9)/('기본-타자'!L9-'기본-타자'!X9-'기본-타자'!Q9+'기본-타자'!Z9),3) -> 0.32 | R9: =ROUND('기본-타자'!AB9-'기본-타자'!AA9,3) -> 0.074 | S9: =ROUND('기본-타자'!AC9-'기본-타자'!AA9,3) -> 0.107 | T9: ='기본-타자'!AK9 -> 0 | U9: ='기본-타자'!AL9 -> 0 | V9: ='기본-타자'!AN9 -> 0 | W9: ='기본-타자'!AM9 -> 0 | X9: ='기본-타자'!AI9 -> 0 | Y9: ='기본-타자'!AJ9 -> 0
